Workbook
Name LastHistYear: 2023
Name Years_Available: [1]Timeseries!$C$8:$AF$8

Sheet QAQC
B2: Quality Assurance and Quality Control
B4: Workbook Information
B5: File Name: | C5: 2021 National Energy Balance 1990-2021 (1st September 2022)
B6: Description of file: | C6: 1990-2021 Energy Balances frozen on 01-Sep-2022
B7: Status: (Draft/ Ongoing /Final)
B10: Versions
C11: Date | D11: High-Level Details
B12: V1.0 | C12: 44805 | D12: 1990-2021 Energy Balances frozen on 01-Sep-2022
B16: QA Checking
B17: Approved by: | C17: Lee Carroll
B18: Position: | C18: Head of SEAI Statistics Unit
B19: Approved date: | C19: 44805

Sheet Timeseries
AP4: =AP8-1990 -> 0 | AQ4: =AQ8-1990 -> 5 | AR4: =AR8-1990 -> 20 | AS4: =AS8-1990 -> 33 | AT4: =AT8-1990 -> 6 | AV4: =AV8-1990+1 -> 1 | AW4: =AW8-1990+1 -> 1 | AX4: =AX8-1990+1 -> 11 | AY4: =AY8-1990+1 -> 19 | AZ4: =AZ8-1990+1 -> 26 | BA4: =BA8-1990+1 -> 27
AV5: =AV9-1990+1 -> 33 | AW5: =AW9-1990+1 -> 11 | AX5: =AX9-1990+1 -> 19 | AY5: =AY9-1990+1 -> 23 | AZ5: =AZ9-1990+1 -> 30 | BA5: =BA9-1990+1 -> 35
AV6: =AV9-AV8 -> 32 | AW6: =AW9-AW8 -> 10 | AX6: =AX9-AX8 -> 8 | AY6: =AY9-AY8 -> 4 | AZ6: =AZ9-AZ8 -> 4 | BA6: =BA9-BA8 -> 8
E7: Time Series | AP7: % Shares | AV7: Average Annual Growth Rate %
D8: TJ | E8: 1990 | F8: =E8+1 -> 1991 | G8: =F8+1 -> 1992 | H8: =G8+1 -> 1993 | I8: =H8+1 -> 1994 | J8: =I8+1 -> 1995 | K8: =J8+1 -> 1996 | L8: =K8+1 -> 1997 | M8: =L8+1 -> 1998 | ... AM8: =AL8+1 -> 2024 | AP8: 1990 | AQ8: 1995 | AR8: 2010 | AS8: 2023 | AT8: 1996 | AV8: 1990 | AW8: 1990 | AX8: 2000 | AY8: 2008 | AZ8: 2015 | BA8: 2016
AV9: 2022 | AW9: 2000 | AX9: 2008 | AY9: 2012 | AZ9: 2019 | BA9: 2024
D10: Road Private Car
B11: 4 | E11: =SUM(E12,E17,E21,E36,E37,E49,E50,E51) -> 38778.282 | F11: =SUM(F12,F17,F21,F36,F37,F49,F50,F51) -> 41086.149 | G11: =SUM(G12,G17,G21,G36,G37,G49,G50,G51) -> 42361.606 | H11: =SUM(H12,H17,H21,H36,H37,H49,H50,H51) -> 44132.402 | I11: =SUM(I12,I17,I21,I36,I37,I49,I50,I51) -> 46636.339 | J11: =SUM(J12,J17,J21,J36,J37,J49,J50,J51) -> 49254.873 | K11: =SUM(K12,K17,K21,K36,K37,K49,K50,K51) -> 52720.822 | L11: =SUM(L12,L17,L21,L36,L37,L49,L50,L51) -> 56440.367 | ... AM11: =SUM(AM12,AM17,AM21,AM36,AM37,AM49,AM50,AM51) -> 90468.312 | AP11: =SUM(AP12,AP17,AP21,AP36,AP37,AP49,AP50,AP51) -> 1 | AQ11: =SUM(AQ12,AQ17,AQ21,AQ36,AQ37,AQ49,AQ50,AQ51) -> 1 | AR11: =SUM(AR12,AR17,AR21,AR36,AR37,AR49,AR50,AR51) -> 1 | AS11: =SUM(AS12,AS17,AS21,AS36,AS37,AS49,AS50,AS51) -> 1 | AT11: =SUM(AT12,AT17,AT21,AT36,AT37,AT49,AT50,AT51) -> 1 | AV11: =IFERROR(POWER(INDEX($E11:$AN11,AV$5)/INDEX($E11:$AN11,AV$4),1/AV$6)-1,) -> 0.024188392 | AW11: =IFERROR(POWER(INDEX($E11:$AN11,AW$5)/INDEX($E11:$AN11,AW$4),1/AW$6)-1,) -> 0.053673842 | AX11: =IFERROR(POWER(INDEX($E11:$AN11,AX$5)/INDEX($E11:$AN11,AX$4),1/AX$6)-1,) -> 0.038327434 | AY11: =IFERROR(POWER(INDEX($E11:$AN11,AY$5)/INDEX($E11:$AN11,AY$4),1/AY$6)-1,) -> -0.006706154 | AZ11: =IFERROR(POWER(INDEX($E11:$AN11,AZ$5)/INDEX($E11:$AN11,AZ$4),1/AZ$6)-1,) -> -0.0091672453 | BA11: =IFERROR(POWER(INDEX($E11:$AN11,BA$5)/INDEX($E11:$AN11,BA$4),1/BA$6)-1,) -> 0.0022584469
A12: =ADDRESS(MATCH($D10,'2021'!$A$1:$A$86,0),MATCH($D12,'2021'!$A$1:$AQ$1,0)) -> $C$48 | B12: =B11+1 -> 5 | D12: Coal | E12: =INDIRECT("'"&E$8&"'!"&$A12)*VLOOKUP($D$8,Tables!$C$1:$D$3,2,0) -> 0 | F12: =INDIRECT("'"&F$8&"'!"&$A12)*VLOOKUP($D$8,Tables!$C$1:$D$3,2,0) -> 0 | G12: =INDIRECT("'"&G$8&"'!"&$A12)*VLOOKUP($D$8,Tables!$C$1:$D$3,2,0) -> 0 | H12: =INDIRECT("'"&H$8&"'!"&$A12)*VLOOKUP($D$8,Tables!$C$1:$D$3,2,0) -> 0 | I12: =INDIRECT("'"&I$8&"'!"&$A12)*VLOOKUP($D$8,Tables!$C$1:$D$3,2,0) -> 0 | J12: =INDIRECT("'"&J$8&"'!"&$A12)*VLOOKUP($D$8,Tables!$C$1:$D$3,2,0) -> 0 | K12: =INDIRECT("'"&K$8&"'!"&$A12)*VLOOKUP($D$8,Tables!$C$1:$D$3,2,0) -> 0 | L12: =INDIRECT("'"&L$8&"'!"&$A12)*VLOOKUP($D$8,Tables!$C$1:$D$3,2,0) -> 0 | ... AM12: =INDIRECT("'"&AM$8&"'!"&$A12)*VLOOKUP($D$8,Tables!$C$1:$D$3,2,0) -> 0 | AP12: =HLOOKUP(AP$8,$E$8:$AP$230,$B12,0)/HLOOKUP(AP$8,$E$8:$AN$230,$B11,0) -> 0 | AQ12: =HLOOKUP(AQ$8,$E$8:$AP$230,$B12,0)/HLOOKUP(AQ$8,$E$8:$AN$230,$B11,0) -> 0 | AR12: =HLOOKUP(AR$8,$E$8:$AP$230,$B12,0)/HLOOKUP(AR$8,$E$8:$AN$230,$B11,0) -> 0 | AS12: =HLOOKUP(AS$8,$E$8:$AP$230,$B12,0)/HLOOKUP(AS$8,$E$8:$AN$230,$B11,0) -> 0 | AT12: =HLOOKUP(AT$8,$E$8:$AN$230,$B12,0)/HLOOKUP(AT$8,$E$8:$AN$230,$B11,0) -> 0 | AV12: =IFERROR(POWER(INDEX($E12:$AN12,AV$5)/INDEX($E12:$AN12,AV$4),1/AV$6)-1,) -> 0 | AW12: =IFERROR(POWER(INDEX($E12:$AN12,AW$5)/INDEX($E12:$AN12,AW$4),1/AW$6)-1,) -> 0 | AX12: =IFERROR(POWER(INDEX($E12:$AN12,AX$5)/INDEX($E12:$AN12,AX$4),1/AX$6)-1,) -> 0 | AY12: =IFERROR(POWER(INDEX($E12:$AN12,AY$5)/INDEX($E12:$AN12,AY$4),1/AY$6)-1,) -> 0 | AZ12: =IFERROR(POWER(INDEX($E12:$AN12,AZ$5)/INDEX($E12:$AN12,AZ$4),1/AZ$6)-1,) -> 0 | BA12: =IFERROR(POWER(INDEX($E12:$AN12,BA$5)/INDEX($E12:$AN12,BA$4),1/BA$6)-1,) -> 0
A13: =ADDRESS(MATCH($D10,'2021'!$A$1:$A$86,0),MATCH($D13,'2021'!$A$1:$AQ$1,0)) -> $D$48 | B13: =B12+1 -> 6 | D13: Bituminous Coal | E13: =INDIRECT("'"&E$8&"'!"&$A13)*VLOOKUP($D$8,Tables!$C$1:$D$3,2,0) -> 0 | F13: =INDIRECT("'"&F$8&"'!"&$A13)*VLOOKUP($D$8,Tables!$C$1:$D$3,2,0) -> 0 | G13: =INDIRECT("'"&G$8&"'!"&$A13)*VLOOKUP($D$8,Tables!$C$1:$D$3,2,0) -> 0 | H13: =INDIRECT("'"&H$8&"'!"&$A13)*VLOOKUP($D$8,Tables!$C$1:$D$3,2,0) -> 0 | I13: =INDIRECT("'"&I$8&"'!"&$A13)*VLOOKUP($D$8,Tables!$C$1:$D$3,2,0) -> 0 | J13: =INDIRECT("'"&J$8&"'!"&$A13)*VLOOKUP($D$8,Tables!$C$1:$D$3,2,0) -> 0 | K13: =INDIRECT("'"&K$8&"'!"&$A13)*VLOOKUP($D$8,Tables!$C$1:$D$3,2,0) -> 0 | L13: =INDIRECT("'"&L$8&"'!"&$A13)*VLOOKUP($D$8,Tables!$C$1:$D$3,2,0) -> 0 | ... AM13: =INDIRECT("'"&AM$8&"'!"&$A13)*VLOOKUP($D$8,Tables!$C$1:$D$3,2,0) -> 0 | AP13: =HLOOKUP(AP$8,$E$8:$AP$230,$B13,0)/HLOOKUP(AP$8,$E$8:$AN$230,$B11,0) -> 0 | AQ13: =HLOOKUP(AQ$8,$E$8:$AP$230,$B13,0)/HLOOKUP(AQ$8,$E$8:$AN$230,$B12,0) -> #DIV/0! | AR13: =HLOOKUP(AR$8,$E$8:$AP$230,$B13,0)/HLOOKUP(AR$8,$E$8:$AN$230,$B11,0) -> 0 | AS13: =HLOOKUP(AS$8,$E$8:$AP$230,$B13,0)/HLOOKUP(AS$8,$E$8:$AN$230,$B11,0) -> 0 | AT13: =HLOOKUP(AT$8,$E$8:$AP$230,$B13,0)/HLOOKUP(AT$8,$E$8:$AN$230,$B11,0) -> 0 | AV13: =IFERROR(POWER(INDEX($E13:$AN13,AV$5)/INDEX($E13:$AN13,AV$4),1/AV$6)-1,) -> 0 | AW13: =IFERROR(POWER(INDEX($E13:$AN13,AW$5)/INDEX($E13:$AN13,AW$4),1/AW$6)-1,) -> 0 | AX13: =IFERROR(POWER(INDEX($E13:$AN13,AX$5)/INDEX($E13:$AN13,AX$4),1/AX$6)-1,) -> 0 | AY13: =IFERROR(POWER(INDEX($E13:$AN13,AY$5)/INDEX($E13:$AN13,AY$4),1/AY$6)-1,) -> 0 | AZ13: =IFERROR(POWER(INDEX($E13:$AN13,AZ$5)/INDEX($E13:$AN13,AZ$4),1/AZ$6)-1,) -> 0 | BA13: =IFERROR(POWER(INDEX($E13:$AN13,BA$5)/INDEX($E13:$AN13,BA$4),1/BA$6)-1,) -> 0
A14: =ADDRESS(MATCH($D10,'2021'!$A$1:$A$86,0),MATCH($D14,'2021'!$A$1:$AQ$1,0)) -> $E$48 | B14: =B13+1 -> 7 | D14: Anthracite + Manufactured Ovoids | E14: =INDIRECT("'"&E$8&"'!"&$A14)*VLOOKUP($D$8,Tables!$C$1:$D$3,2,0) -> 0 | F14: =INDIRECT("'"&F$8&"'!"&$A14)*VLOOKUP($D$8,Tables!$C$1:$D$3,2,0) -> 0 | G14: =INDIRECT("'"&G$8&"'!"&$A14)*VLOOKUP($D$8,Tables!$C$1:$D$3,2,0) -> 0 | H14: =INDIRECT("'"&H$8&"'!"&$A14)*VLOOKUP($D$8,Tables!$C$1:$D$3,2,0) -> 0 | I14: =INDIRECT("'"&I$8&"'!"&$A14)*VLOOKUP($D$8,Tables!$C$1:$D$3,2,0) -> 0 | J14: =INDIRECT("'"&J$8&"'!"&$A14)*VLOOKUP($D$8,Tables!$C$1:$D$3,2,0) -> 0 | K14: =INDIRECT("'"&K$8&"'!"&$A14)*VLOOKUP($D$8,Tables!$C$1:$D$3,2,0) -> 0 | L14: =INDIRECT("'"&L$8&"'!"&$A14)*VLOOKUP($D$8,Tables!$C$1:$D$3,2,0) -> 0 | ... AM14: =INDIRECT("'"&AM$8&"'!"&$A14)*VLOOKUP($D$8,Tables!$C$1:$D$3,2,0) -> 0 | AP14: =HLOOKUP(AP$8,$E$8:$AP$230,$B14,0)/HLOOKUP(AP$8,$E$8:$AN$230,$B11,0) -> 0 | AQ14: =HLOOKUP(AQ$8,$E$8:$AP$230,$B14,0)/HLOOKUP(AQ$8,$E$8:$AN$230,$B13,0) -> #DIV/0! | AR14: =HLOOKUP(AR$8,$E$8:$AP$230,$B14,0)/HLOOKUP(AR$8,$E$8:$AN$230,$B11,0) -> 0 | AS14: =HLOOKUP(AS$8,$E$8:$AP$230,$B14,0)/HLOOKUP(AS$8,$E$8:$AN$230,$B11,0) -> 0 | AT14: =HLOOKUP(AT$8,$E$8:$AP$230,$B14,0)/HLOOKUP(AT$8,$E$8:$AN$230,$B11,0) -> 0 | AV14: =IFERROR(POWER(INDEX($E14:$AN14,AV$5)/INDEX($E14:$AN14,AV$4),1/AV$6)-1,) -> 0 | AW14: =IFERROR(POWER(INDEX($E14:$AN14,AW$5)/INDEX($E14:$AN14,AW$4),1/AW$6)-1,) -> 0 | AX14: =IFERROR(POWER(INDEX($E14:$AN14,AX$5)/INDEX($E14:$AN14,AX$4),1/AX$6)-1,) -> 0 | AY14: =IFERROR(POWER(INDEX($E14:$AN14,AY$5)/INDEX($E14:$AN14,AY$4),1/AY$6)-1,) -> 0 | AZ14: =IFERROR(POWER(INDEX($E14:$AN14,AZ$5)/INDEX($E14:$AN14,AZ$4),1/AZ$6)-1,) -> 0 | BA14: =IFERROR(POWER(INDEX($E14:$AN14,BA$5)/INDEX($E14:$AN14,BA$4),1/BA$6)-1,) -> 0
A15: =ADDRESS(MATCH($D10,'2021'!$A$1:$A$86,0),MATCH($D15,'2021'!$A$1:$AQ$1,0)) -> $F$48 | B15: =B14+1 -> 8 | D15: Coke | E15: =INDIRECT("'"&E$8&"'!"&$A15)*VLOOKUP($D$8,Tables!$C$1:$D$3,2,0) -> 0 | F15: =INDIRECT("'"&F$8&"'!"&$A15)*VLOOKUP($D$8,Tables!$C$1:$D$3,2,0) -> 0 | G15: =INDIRECT("'"&G$8&"'!"&$A15)*VLOOKUP($D$8,Tables!$C$1:$D$3,2,0) -> 0 | H15: =INDIRECT("'"&H$8&"'!"&$A15)*VLOOKUP($D$8,Tables!$C$1:$D$3,2,0) -> 0 | I15: =INDIRECT("'"&I$8&"'!"&$A15)*VLOOKUP($D$8,Tables!$C$1:$D$3,2,0) -> 0 | J15: =INDIRECT("'"&J$8&"'!"&$A15)*VLOOKUP($D$8,Tables!$C$1:$D$3,2,0) -> 0 | K15: =INDIRECT("'"&K$8&"'!"&$A15)*VLOOKUP($D$8,Tables!$C$1:$D$3,2,0) -> 0 | L15: =INDIRECT("'"&L$8&"'!"&$A15)*VLOOKUP($D$8,Tables!$C$1:$D$3,2,0) -> 0 | ... AM15: =INDIRECT("'"&AM$8&"'!"&$A15)*VLOOKUP($D$8,Tables!$C$1:$D$3,2,0) -> 0 | AP15: =HLOOKUP(AP$8,$E$8:$AP$230,$B15,0)/HLOOKUP(AP$8,$E$8:$AN$230,$B11,0) -> 0 | AQ15: =HLOOKUP(AQ$8,$E$8:$AP$230,$B15,0)/HLOOKUP(AQ$8,$E$8:$AN$230,$B14,0) -> #DIV/0! | AR15: =HLOOKUP(AR$8,$E$8:$AP$230,$B15,0)/HLOOKUP(AR$8,$E$8:$AN$230,$B11,0) -> 0 | AS15: =HLOOKUP(AS$8,$E$8:$AP$230,$B15,0)/HLOOKUP(AS$8,$E$8:$AN$230,$B11,0) -> 0 | AT15: =HLOOKUP(AT$8,$E$8:$AP$230,$B15,0)/HLOOKUP(AT$8,$E$8:$AN$230,$B11,0) -> 0 | AV15: =IFERROR(POWER(INDEX($E15:$AN15,AV$5)/INDEX($E15:$AN15,AV$4),1/AV$6)-1,) -> 0 | AW15: =IFERROR(POWER(INDEX($E15:$AN15,AW$5)/INDEX($E15:$AN15,AW$4),1/AW$6)-1,) -> 0 | AX15: =IFERROR(POWER(INDEX($E15:$AN15,AX$5)/INDEX($E15:$AN15,AX$4),1/AX$6)-1,) -> 0 | AY15: =IFERROR(POWER(INDEX($E15:$AN15,AY$5)/INDEX($E15:$AN15,AY$4),1/AY$6)-1,) -> 0 | AZ15: =IFERROR(POWER(INDEX($E15:$AN15,AZ$5)/INDEX($E15:$AN15,AZ$4),1/AZ$6)-1,) -> 0 | BA15: =IFERROR(POWER(INDEX($E15:$AN15,BA$5)/INDEX($E15:$AN15,BA$4),1/BA$6)-1,) -> 0
A16: =ADDRESS(MATCH($D10,'2021'!$A$1:$A$86,0),MATCH($D16,'2021'!$A$1:$AQ$1,0)) -> $G$48 | B16: =B15+1 -> 9 | D16: Lignite \ Brown Coal Briquettes | E16: =INDIRECT("'"&E$8&"'!"&$A16)*VLOOKUP($D$8,Tables!$C$1:$D$3,2,0) -> 0 | F16: =INDIRECT("'"&F$8&"'!"&$A16)*VLOOKUP($D$8,Tables!$C$1:$D$3,2,0) -> 0 | G16: =INDIRECT("'"&G$8&"'!"&$A16)*VLOOKUP($D$8,Tables!$C$1:$D$3,2,0) -> 0 | H16: =INDIRECT("'"&H$8&"'!"&$A16)*VLOOKUP($D$8,Tables!$C$1:$D$3,2,0) -> 0 | I16: =INDIRECT("'"&I$8&"'!"&$A16)*VLOOKUP($D$8,Tables!$C$1:$D$3,2,0) -> 0 | J16: =INDIRECT("'"&J$8&"'!"&$A16)*VLOOKUP($D$8,Tables!$C$1:$D$3,2,0) -> 0 | K16: =INDIRECT("'"&K$8&"'!"&$A16)*VLOOKUP($D$8,Tables!$C$1:$D$3,2,0) -> 0 | L16: =INDIRECT("'"&L$8&"'!"&$A16)*VLOOKUP($D$8,Tables!$C$1:$D$3,2,0) -> 0 | ... AM16: =INDIRECT("'"&AM$8&"'!"&$A16)*VLOOKUP($D$8,Tables!$C$1:$D$3,2,0) -> 0 | AP16: =HLOOKUP(AP$8,$E$8:$AP$230,$B16,0)/HLOOKUP(AP$8,$E$8:$AN$230,$B11,0) -> 0 | AQ16: =HLOOKUP(AQ$8,$E$8:$AP$230,$B16,0)/HLOOKUP(AQ$8,$E$8:$AN$230,$B15,0) -> #DIV/0! | AR16: =HLOOKUP(AR$8,$E$8:$AP$230,$B16,0)/HLOOKUP(AR$8,$E$8:$AN$230,$B11,0) -> 0 | AS16: =HLOOKUP(AS$8,$E$8:$AP$230,$B16,0)/HLOOKUP(AS$8,$E$8:$AN$230,$B11,0) -> 0 | AT16: =HLOOKUP(AT$8,$E$8:$AP$230,$B16,0)/HLOOKUP(AT$8,$E$8:$AN$230,$B11,0) -> 0 | AV16: =IFERROR(POWER(INDEX($E16:$AN16,AV$5)/INDEX($E16:$AN16,AV$4),1/AV$6)-1,) -> 0 | AW16: =IFERROR(POWER(INDEX($E16:$AN16,AW$5)/INDEX($E16:$AN16,AW$4),1/AW$6)-1,) -> 0 | AX16: =IFERROR(POWER(INDEX($E16:$AN16,AX$5)/INDEX($E16:$AN16,AX$4),1/AX$6)-1,) -> 0 | AY16: =IFERROR(POWER(INDEX($E16:$AN16,AY$5)/INDEX($E16:$AN16,AY$4),1/AY$6)-1,) -> 0 | AZ16: =IFERROR(POWER(INDEX($E16:$AN16,AZ$5)/INDEX($E16:$AN16,AZ$4),1/AZ$6)-1,) -> 0 | BA16: =IFERROR(POWER(INDEX($E16:$AN16,BA$5)/INDEX($E16:$AN16,BA$4),1/BA$6)-1,) -> 0
A17: =ADDRESS(MATCH($D10,'2021'!$A$1:$A$86,0),MATCH($D17,'2021'!$A$1:$AQ$1,0)) -> $H$48 | B17: =B16+1 -> 10 | D17: Peat | E17: =INDIRECT("'"&E$8&"'!"&$A17)*VLOOKUP($D$8,Tables!$C$1:$D$3,2,0) -> 0 | F17: =INDIRECT("'"&F$8&"'!"&$A17)*VLOOKUP($D$8,Tables!$C$1:$D$3,2,0) -> 0 | G17: =INDIRECT("'"&G$8&"'!"&$A17)*VLOOKUP($D$8,Tables!$C$1:$D$3,2,0) -> 0 | H17: =INDIRECT("'"&H$8&"'!"&$A17)*VLOOKUP($D$8,Tables!$C$1:$D$3,2,0) -> 0 | I17: =INDIRECT("'"&I$8&"'!"&$A17)*VLOOKUP($D$8,Tables!$C$1:$D$3,2,0) -> 0 | J17: =INDIRECT("'"&J$8&"'!"&$A17)*VLOOKUP($D$8,Tables!$C$1:$D$3,2,0) -> 0 | K17: =INDIRECT("'"&K$8&"'!"&$A17)*VLOOKUP($D$8,Tables!$C$1:$D$3,2,0) -> 0 | L17: =INDIRECT("'"&L$8&"'!"&$A17)*VLOOKUP($D$8,Tables!$C$1:$D$3,2,0) -> 0 | ... AM17: =INDIRECT("'"&AM$8&"'!"&$A17)*VLOOKUP($D$8,Tables!$C$1:$D$3,2,0) -> 0 | AP17: =HLOOKUP(AP$8,$E$8:$AP$230,$B17,0)/HLOOKUP(AP$8,$E$8:$AN$230,$B11,0) -> 0 | AQ17: =HLOOKUP(AQ$8,$E$8:$AP$230,$B17,0)/HLOOKUP(AQ$8,$E$8:$AN$230,$B11,0) -> 0 | AR17: =HLOOKUP(AR$8,$E$8:$AP$230,$B17,0)/HLOOKUP(AR$8,$E$8:$AN$230,$B11,0) -> 0 | AS17: =HLOOKUP(AS$8,$E$8:$AP$230,$B17,0)/HLOOKUP(AS$8,$E$8:$AN$230,$B11,0) -> 0 | AT17: =HLOOKUP(AT$8,$E$8:$AP$230,$B17,0)/HLOOKUP(AT$8,$E$8:$AN$230,$B11,0) -> 0 | AV17: =IFERROR(POWER(INDEX($E17:$AN17,AV$5)/INDEX($E17:$AN17,AV$4),1/AV$6)-1,) -> 0 | AW17: =IFERROR(POWER(INDEX($E17:$AN17,AW$5)/INDEX($E17:$AN17,AW$4),1/AW$6)-1,) -> 0 | AX17: =IFERROR(POWER(INDEX($E17:$AN17,AX$5)/INDEX($E17:$AN17,AX$4),1/AX$6)-1,) -> 0 | AY17: =IFERROR(POWER(INDEX($E17:$AN17,AY$5)/INDEX($E17:$AN17,AY$4),1/AY$6)-1,) -> 0 | AZ17: =IFERROR(POWER(INDEX($E17:$AN17,AZ$5)/INDEX($E17:$AN17,AZ$4),1/AZ$6)-1,) -> 0 | BA17: =IFERROR(POWER(INDEX($E17:$AN17,BA$5)/INDEX($E17:$AN17,BA$4),1/BA$6)-1,) -> 0
A18: =ADDRESS(MATCH($D10,'2021'!$A$1:$A$86,0),MATCH($D18,'2021'!$A$1:$AQ$1,0)) -> $I$48 | B18: =B17+1 -> 11 | D18: Milled Peat | E18: =INDIRECT("'"&E$8&"'!"&$A18)*VLOOKUP($D$8,Tables!$C$1:$D$3,2,0) -> 0 | F18: =INDIRECT("'"&F$8&"'!"&$A18)*VLOOKUP($D$8,Tables!$C$1:$D$3,2,0) -> 0 | G18: =INDIRECT("'"&G$8&"'!"&$A18)*VLOOKUP($D$8,Tables!$C$1:$D$3,2,0) -> 0 | H18: =INDIRECT("'"&H$8&"'!"&$A18)*VLOOKUP($D$8,Tables!$C$1:$D$3,2,0) -> 0 | I18: =INDIRECT("'"&I$8&"'!"&$A18)*VLOOKUP($D$8,Tables!$C$1:$D$3,2,0) -> 0 | J18: =INDIRECT("'"&J$8&"'!"&$A18)*VLOOKUP($D$8,Tables!$C$1:$D$3,2,0) -> 0 | K18: =INDIRECT("'"&K$8&"'!"&$A18)*VLOOKUP($D$8,Tables!$C$1:$D$3,2,0) -> 0 | L18: =INDIRECT("'"&L$8&"'!"&$A18)*VLOOKUP($D$8,Tables!$C$1:$D$3,2,0) -> 0 | ... AM18: =INDIRECT("'"&AM$8&"'!"&$A18)*VLOOKUP($D$8,Tables!$C$1:$D$3,2,0) -> 0 | AP18: =HLOOKUP(AP$8,$E$8:$AP$230,$B18,0)/HLOOKUP(AP$8,$E$8:$AN$230,$B11,0) -> 0 | AQ18: =HLOOKUP(AQ$8,$E$8:$AP$230,$B18,0)/HLOOKUP(AQ$8,$E$8:$AN$230,$B11,0) -> 0 | AR18: =HLOOKUP(AR$8,$E$8:$AP$230,$B18,0)/HLOOKUP(AR$8,$E$8:$AN$230,$B11,0) -> 0 | AS18: =HLOOKUP(AS$8,$E$8:$AP$230,$B18,0)/HLOOKUP(AS$8,$E$8:$AN$230,$B11,0) -> 0 | AT18: =HLOOKUP(AT$8,$E$8:$AP$230,$B18,0)/HLOOKUP(AT$8,$E$8:$AN$230,$B11,0) -> 0 | AV18: =IFERROR(POWER(INDEX($E18:$AN18,AV$5)/INDEX($E18:$AN18,AV$4),1/AV$6)-1,) -> 0 | AW18: =IFERROR(POWER(INDEX($E18:$AN18,AW$5)/INDEX($E18:$AN18,AW$4),1/AW$6)-1,) -> 0 | AX18: =IFERROR(POWER(INDEX($E18:$AN18,AX$5)/INDEX($E18:$AN18,AX$4),1/AX$6)-1,) -> 0 | AY18: =IFERROR(POWER(INDEX($E18:$AN18,AY$5)/INDEX($E18:$AN18,AY$4),1/AY$6)-1,) -> 0 | AZ18: =IFERROR(POWER(INDEX($E18:$AN18,AZ$5)/INDEX($E18:$AN18,AZ$4),1/AZ$6)-1,) -> 0 | BA18: =IFERROR(POWER(INDEX($E18:$AN18,BA$5)/INDEX($E18:$AN18,BA$4),1/BA$6)-1,) -> 0
A19: =ADDRESS(MATCH($D10,'2021'!$A$1:$A$86,0),MATCH($D19,'2021'!$A$1:$AQ$1,0)) -> $J$48 | B19: =B18+1 -> 12 | D19: Sod Peat | E19: =INDIRECT("'"&E$8&"'!"&$A19)*VLOOKUP($D$8,Tables!$C$1:$D$3,2,0) -> 0 | F19: =INDIRECT("'"&F$8&"'!"&$A19)*VLOOKUP($D$8,Tables!$C$1:$D$3,2,0) -> 0 | G19: =INDIRECT("'"&G$8&"'!"&$A19)*VLOOKUP($D$8,Tables!$C$1:$D$3,2,0) -> 0 | H19: =INDIRECT("'"&H$8&"'!"&$A19)*VLOOKUP($D$8,Tables!$C$1:$D$3,2,0) -> 0 | I19: =INDIRECT("'"&I$8&"'!"&$A19)*VLOOKUP($D$8,Tables!$C$1:$D$3,2,0) -> 0 | J19: =INDIRECT("'"&J$8&"'!"&$A19)*VLOOKUP($D$8,Tables!$C$1:$D$3,2,0) -> 0 | K19: =INDIRECT("'"&K$8&"'!"&$A19)*VLOOKUP($D$8,Tables!$C$1:$D$3,2,0) -> 0 | L19: =INDIRECT("'"&L$8&"'!"&$A19)*VLOOKUP($D$8,Tables!$C$1:$D$3,2,0) -> 0 | ... AM19: =INDIRECT("'"&AM$8&"'!"&$A19)*VLOOKUP($D$8,Tables!$C$1:$D$3,2,0) -> 0 | AP19: =HLOOKUP(AP$8,$E$8:$AP$230,$B19,0)/HLOOKUP(AP$8,$E$8:$AN$230,$B11,0) -> 0 | AQ19: =HLOOKUP(AQ$8,$E$8:$AP$230,$B19,0)/HLOOKUP(AQ$8,$E$8:$AN$230,$B11,0) -> 0 | AR19: =HLOOKUP(AR$8,$E$8:$AP$230,$B19,0)/HLOOKUP(AR$8,$E$8:$AN$230,$B11,0) -> 0 | AS19: =HLOOKUP(AS$8,$E$8:$AP$230,$B19,0)/HLOOKUP(AS$8,$E$8:$AN$230,$B11,0) -> 0 | AT19: =HLOOKUP(AT$8,$E$8:$AP$230,$B19,0)/HLOOKUP(AT$8,$E$8:$AN$230,$B11,0) -> 0 | AV19: =IFERROR(POWER(INDEX($E19:$AN19,AV$5)/INDEX($E19:$AN19,AV$4),1/AV$6)-1,) -> 0 | AW19: =IFERROR(POWER(INDEX($E19:$AN19,AW$5)/INDEX($E19:$AN19,AW$4),1/AW$6)-1,) -> 0 | AX19: =IFERROR(POWER(INDEX($E19:$AN19,AX$5)/INDEX($E19:$AN19,AX$4),1/AX$6)-1,) -> 0 | AY19: =IFERROR(POWER(INDEX($E19:$AN19,AY$5)/INDEX($E19:$AN19,AY$4),1/AY$6)-1,) -> 0 | AZ19: =IFERROR(POWER(INDEX($E19:$AN19,AZ$5)/INDEX($E19:$AN19,AZ$4),1/AZ$6)-1,) -> 0 | BA19: =IFERROR(POWER(INDEX($E19:$AN19,BA$5)/INDEX($E19:$AN19,BA$4),1/BA$6)-1,) -> 0
A20: =ADDRESS(MATCH($D10,'2021'!$A$1:$A$86,0),MATCH($D20,'2021'!$A$1:$AQ$1,0)) -> $K$48 | B20: =B19+1 -> 13 | D20: Briquettes | E20: =INDIRECT("'"&E$8&"'!"&$A20)*VLOOKUP($D$8,Tables!$C$1:$D$3,2,0) -> 0 | F20: =INDIRECT("'"&F$8&"'!"&$A20)*VLOOKUP($D$8,Tables!$C$1:$D$3,2,0) -> 0 | G20: =INDIRECT("'"&G$8&"'!"&$A20)*VLOOKUP($D$8,Tables!$C$1:$D$3,2,0) -> 0 | H20: =INDIRECT("'"&H$8&"'!"&$A20)*VLOOKUP($D$8,Tables!$C$1:$D$3,2,0) -> 0 | I20: =INDIRECT("'"&I$8&"'!"&$A20)*VLOOKUP($D$8,Tables!$C$1:$D$3,2,0) -> 0 | J20: =INDIRECT("'"&J$8&"'!"&$A20)*VLOOKUP($D$8,Tables!$C$1:$D$3,2,0) -> 0 | K20: =INDIRECT("'"&K$8&"'!"&$A20)*VLOOKUP($D$8,Tables!$C$1:$D$3,2,0) -> 0 | L20: =INDIRECT("'"&L$8&"'!"&$A20)*VLOOKUP($D$8,Tables!$C$1:$D$3,2,0) -> 0 | ... AM20: =INDIRECT("'"&AM$8&"'!"&$A20)*VLOOKUP($D$8,Tables!$C$1:$D$3,2,0) -> 0 | AP20: =HLOOKUP(AP$8,$E$8:$AP$230,$B20,0)/HLOOKUP(AP$8,$E$8:$AN$230,$B11,0) -> 0 | AQ20: =HLOOKUP(AQ$8,$E$8:$AP$230,$B20,0)/HLOOKUP(AQ$8,$E$8:$AN$230,$B11,0) -> 0 | AR20: =HLOOKUP(AR$8,$E$8:$AP$230,$B20,0)/HLOOKUP(AR$8,$E$8:$AN$230,$B11,0) -> 0 | AS20: =HLOOKUP(AS$8,$E$8:$AP$230,$B20,0)/HLOOKUP(AS$8,$E$8:$AN$230,$B11,0) -> 0 | AT20: =HLOOKUP(AT$8,$E$8:$AP$230,$B20,0)/HLOOKUP(AT$8,$E$8:$AN$230,$B11,0) -> 0 | AV20: =IFERROR(POWER(INDEX($E20:$AN20,AV$5)/INDEX($E20:$AN20,AV$4),1/AV$6)-1,) -> 0 | AW20: =IFERROR(POWER(INDEX($E20:$AN20,AW$5)/INDEX($E20:$AN20,AW$4),1/AW$6)-1,) -> 0 | AX20: =IFERROR(POWER(INDEX($E20:$AN20,AX$5)/INDEX($E20:$AN20,AX$4),1/AX$6)-1,) -> 0 | AY20: =IFERROR(POWER(INDEX($E20:$AN20,AY$5)/INDEX($E20:$AN20,AY$4),1/AY$6)-1,) -> 0 | AZ20: =IFERROR(POWER(INDEX($E20:$AN20,AZ$5)/INDEX($E20:$AN20,AZ$4),1/AZ$6)-1,) -> 0 | BA20: =IFERROR(POWER(INDEX($E20:$AN20,BA$5)/INDEX($E20:$AN20,BA$4),1/BA$6)-1,) -> 0
A21: =ADDRESS(MATCH($D10,'2021'!$A$1:$A$86,0),MATCH($D21,'2021'!$A$1:$AQ$1,0)) -> $L$48 | B21: =B20+1 -> 14 | D21: Oil | E21: =INDIRECT("'"&E$8&"'!"&$A21)*VLOOKUP($D$8,Tables!$C$1:$D$3,2,0) -> 38778.282 | F21: =INDIRECT("'"&F$8&"'!"&$A21)*VLOOKUP($D$8,Tables!$C$1:$D$3,2,0) -> 41086.149 | G21: =INDIRECT("'"&G$8&"'!"&$A21)*VLOOKUP($D$8,Tables!$C$1:$D$3,2,0) -> 42361.606 | H21: =INDIRECT("'"&H$8&"'!"&$A21)*VLOOKUP($D$8,Tables!$C$1:$D$3,2,0) -> 44132.402 | I21: =INDIRECT("'"&I$8&"'!"&$A21)*VLOOKUP($D$8,Tables!$C$1:$D$3,2,0) -> 46636.339 | J21: =INDIRECT("'"&J$8&"'!"&$A21)*VLOOKUP($D$8,Tables!$C$1:$D$3,2,0) -> 49254.873 | K21: =INDIRECT("'"&K$8&"'!"&$A21)*VLOOKUP($D$8,Tables!$C$1:$D$3,2,0) -> 52720.822 | L21: =INDIRECT("'"&L$8&"'!"&$A21)*VLOOKUP($D$8,Tables!$C$1:$D$3,2,0) -> 56440.367 | ... AM21: =INDIRECT("'"&AM$8&"'!"&$A21)*VLOOKUP($D$8,Tables!$C$1:$D$3,2,0) -> 82062.355 | AP21: =HLOOKUP(AP$8,$E$8:$AP$230,$B21,0)/HLOOKUP(AP$8,$E$8:$AN$230,$B11,0) -> 1 | AQ21: =HLOOKUP(AQ$8,$E$8:$AP$230,$B21,0)/HLOOKUP(AQ$8,$E$8:$AN$230,$B11,0) -> 1 | AR21: =HLOOKUP(AR$8,$E$8:$AP$230,$B21,0)/HLOOKUP(AR$8,$E$8:$AN$230,$B11,0) -> 0.97628196 | AS21: =HLOOKUP(AS$8,$E$8:$AP$230,$B21,0)/HLOOKUP(AS$8,$E$8:$AN$230,$B11,0) -> 0.92004593 | AT21: =HLOOKUP(AT$8,$E$8:$AP$230,$B21,0)/HLOOKUP(AT$8,$E$8:$AN$230,$B11,0) -> 1 | AV21: =IFERROR(POWER(INDEX($E21:$AN21,AV$5)/INDEX($E21:$AN21,AV$4),1/AV$6)-1,) -> 0.022142598 | AW21: =IFERROR(POWER(INDEX($E21:$AN21,AW$5)/INDEX($E21:$AN21,AW$4),1/AW$6)-1,) -> 0.053673842 | AX21: =IFERROR(POWER(INDEX($E21:$AN21,AX$5)/INDEX($E21:$AN21,AX$4),1/AX$6)-1,) -> 0.036738054 | AY21: =IFERROR(POWER(INDEX($E21:$AN21,AY$5)/INDEX($E21:$AN21,AY$4),1/AY$6)-1,) -> -0.0096086791 | AZ21: =IFERROR(POWER(INDEX($E21:$AN21,AZ$5)/INDEX($E21:$AN21,AZ$4),1/AZ$6)-1,) -> -0.012865516 | BA21: =IFERROR(POWER(INDEX($E21:$AN21,BA$5)/INDEX($E21:$AN21,BA$4),1/BA$6)-1,) -> -0.0060480713
A22: =ADDRESS(MATCH($D10,'2021'!$A$1:$A$86,0),MATCH($D22,'2021'!$A$1:$AQ$1,0)) -> $M$48 | B22: =B21+1 -> 15 | D22: Crude | E22: =INDIRECT("'"&E$8&"'!"&$A22)*VLOOKUP($D$8,Tables!$C$1:$D$3,2,0) -> 0 | F22: =INDIRECT("'"&F$8&"'!"&$A22)*VLOOKUP($D$8,Tables!$C$1:$D$3,2,0) -> 0 | G22: =INDIRECT("'"&G$8&"'!"&$A22)*VLOOKUP($D$8,Tables!$C$1:$D$3,2,0) -> 0 | H22: =INDIRECT("'"&H$8&"'!"&$A22)*VLOOKUP($D$8,Tables!$C$1:$D$3,2,0) -> 0 | I22: =INDIRECT("'"&I$8&"'!"&$A22)*VLOOKUP($D$8,Tables!$C$1:$D$3,2,0) -> 0 | J22: =INDIRECT("'"&J$8&"'!"&$A22)*VLOOKUP($D$8,Tables!$C$1:$D$3,2,0) -> 0 | K22: =INDIRECT("'"&K$8&"'!"&$A22)*VLOOKUP($D$8,Tables!$C$1:$D$3,2,0) -> 0 | L22: =INDIRECT("'"&L$8&"'!"&$A22)*VLOOKUP($D$8,Tables!$C$1:$D$3,2,0) -> 0 | ... AM22: =INDIRECT("'"&AM$8&"'!"&$A22)*VLOOKUP($D$8,Tables!$C$1:$D$3,2,0) -> 0 | AP22: =HLOOKUP(AP$8,$E$8:$AP$230,$B22,0)/HLOOKUP(AP$8,$E$8:$AN$230,$B11,0) -> 0 | AQ22: =HLOOKUP(AQ$8,$E$8:$AP$230,$B22,0)/HLOOKUP(AQ$8,$E$8:$AN$230,$B11,0) -> 0 | AR22: =HLOOKUP(AR$8,$E$8:$AP$230,$B22,0)/HLOOKUP(AR$8,$E$8:$AN$230,$B11,0) -> 0 | AS22: =HLOOKUP(AS$8,$E$8:$AP$230,$B22,0)/HLOOKUP(AS$8,$E$8:$AN$230,$B11,0) -> 0 | AT22: =HLOOKUP(AT$8,$E$8:$AP$230,$B22,0)/HLOOKUP(AT$8,$E$8:$AN$230,$B11,0) -> 0 | AV22: =IFERROR(POWER(INDEX($E22:$AN22,AV$5)/INDEX($E22:$AN22,AV$4),1/AV$6)-1,) -> 0 | AW22: =IFERROR(POWER(INDEX($E22:$AN22,AW$5)/INDEX($E22:$AN22,AW$4),1/AW$6)-1,) -> 0 | AX22: =IFERROR(POWER(INDEX($E22:$AN22,AX$5)/INDEX($E22:$AN22,AX$4),1/AX$6)-1,) -> 0 | AY22: =IFERROR(POWER(INDEX($E22:$AN22,AY$5)/INDEX($E22:$AN22,AY$4),1/AY$6)-1,) -> 0 | AZ22: =IFERROR(POWER(INDEX($E22:$AN22,AZ$5)/INDEX($E22:$AN22,AZ$4),1/AZ$6)-1,) -> 0 | BA22: =IFERROR(POWER(INDEX($E22:$AN22,BA$5)/INDEX($E22:$AN22,BA$4),1/BA$6)-1,) -> 0
A23: =ADDRESS(MATCH($D10,'2021'!$A$1:$A$86,0),MATCH($D23,'2021'!$A$1:$AQ$1,0)) -> $N$48 | B23: =B22+1 -> 16 | D23: Refinery Feedstocks | E23: =INDIRECT("'"&E$8&"'!"&$A23)*VLOOKUP($D$8,Tables!$C$1:$D$3,2,0) -> 0 | F23: =INDIRECT("'"&F$8&"'!"&$A23)*VLOOKUP($D$8,Tables!$C$1:$D$3,2,0) -> 0 | G23: =INDIRECT("'"&G$8&"'!"&$A23)*VLOOKUP($D$8,Tables!$C$1:$D$3,2,0) -> 0 | H23: =INDIRECT("'"&H$8&"'!"&$A23)*VLOOKUP($D$8,Tables!$C$1:$D$3,2,0) -> 0 | I23: =INDIRECT("'"&I$8&"'!"&$A23)*VLOOKUP($D$8,Tables!$C$1:$D$3,2,0) -> 0 | J23: =INDIRECT("'"&J$8&"'!"&$A23)*VLOOKUP($D$8,Tables!$C$1:$D$3,2,0) -> 0 | K23: =INDIRECT("'"&K$8&"'!"&$A23)*VLOOKUP($D$8,Tables!$C$1:$D$3,2,0) -> 0 | L23: =INDIRECT("'"&L$8&"'!"&$A23)*VLOOKUP($D$8,Tables!$C$1:$D$3,2,0) -> 0 | ... AM23: =INDIRECT("'"&AM$8&"'!"&$A23)*VLOOKUP($D$8,Tables!$C$1:$D$3,2,0) -> 0 | AP23: =HLOOKUP(AP$8,$E$8:$AP$230,$B23,0)/HLOOKUP(AP$8,$E$8:$AN$230,$B11,0) -> 0 | AQ23: =HLOOKUP(AQ$8,$E$8:$AP$230,$B23,0)/HLOOKUP(AQ$8,$E$8:$AN$230,$B11,0) -> 0 | AR23: =HLOOKUP(AR$8,$E$8:$AP$230,$B23,0)/HLOOKUP(AR$8,$E$8:$AN$230,$B11,0) -> 0 | AS23: =HLOOKUP(AS$8,$E$8:$AP$230,$B23,0)/HLOOKUP(AS$8,$E$8:$AN$230,$B11,0) -> 0 | AT23: =HLOOKUP(AT$8,$E$8:$AP$230,$B23,0)/HLOOKUP(AT$8,$E$8:$AN$230,$B11,0) -> 0 | AV23: =IFERROR(POWER(INDEX($E23:$AN23,AV$5)/INDEX($E23:$AN23,AV$4),1/AV$6)-1,) -> 0 | AW23: =IFERROR(POWER(INDEX($E23:$AN23,AW$5)/INDEX($E23:$AN23,AW$4),1/AW$6)-1,) -> 0 | AX23: =IFERROR(POWER(INDEX($E23:$AN23,AX$5)/INDEX($E23:$AN23,AX$4),1/AX$6)-1,) -> 0 | AY23: =IFERROR(POWER(INDEX($E23:$AN23,AY$5)/INDEX($E23:$AN23,AY$4),1/AY$6)-1,) -> 0 | AZ23: =IFERROR(POWER(INDEX($E23:$AN23,AZ$5)/INDEX($E23:$AN23,AZ$4),1/AZ$6)-1,) -> 0 | BA23: =IFERROR(POWER(INDEX($E23:$AN23,BA$5)/INDEX($E23:$AN23,BA$4),1/BA$6)-1,) -> 0
A24: =ADDRESS(MATCH($D10,'2021'!$A$1:$A$86,0),MATCH($D24,'2021'!$A$1:$AQ$1,0)) -> $O$48 | B24: =B23+1 -> 17 | D24: Refinery Gas | E24: =INDIRECT("'"&E$8&"'!"&$A24)*VLOOKUP($D$8,Tables!$C$1:$D$3,2,0) -> 0 | F24: =INDIRECT("'"&F$8&"'!"&$A24)*VLOOKUP($D$8,Tables!$C$1:$D$3,2,0) -> 0 | G24: =INDIRECT("'"&G$8&"'!"&$A24)*VLOOKUP($D$8,Tables!$C$1:$D$3,2,0) -> 0 | H24: =INDIRECT("'"&H$8&"'!"&$A24)*VLOOKUP($D$8,Tables!$C$1:$D$3,2,0) -> 0 | I24: =INDIRECT("'"&I$8&"'!"&$A24)*VLOOKUP($D$8,Tables!$C$1:$D$3,2,0) -> 0 | J24: =INDIRECT("'"&J$8&"'!"&$A24)*VLOOKUP($D$8,Tables!$C$1:$D$3,2,0) -> 0 | K24: =INDIRECT("'"&K$8&"'!"&$A24)*VLOOKUP($D$8,Tables!$C$1:$D$3,2,0) -> 0 | L24: =INDIRECT("'"&L$8&"'!"&$A24)*VLOOKUP($D$8,Tables!$C$1:$D$3,2,0) -> 0 | ... AM24: =INDIRECT("'"&AM$8&"'!"&$A24)*VLOOKUP($D$8,Tables!$C$1:$D$3,2,0) -> 0 | AP24: =HLOOKUP(AP$8,$E$8:$AP$230,$B24,0)/HLOOKUP(AP$8,$E$8:$AN$230,$B11,0) -> 0 | AQ24: =HLOOKUP(AQ$8,$E$8:$AP$230,$B24,0)/HLOOKUP(AQ$8,$E$8:$AN$230,$B11,0) -> 0 | AR24: =HLOOKUP(AR$8,$E$8:$AP$230,$B24,0)/HLOOKUP(AR$8,$E$8:$AN$230,$B11,0) -> 0 | AS24: =HLOOKUP(AS$8,$E$8:$AP$230,$B24,0)/HLOOKUP(AS$8,$E$8:$AN$230,$B11,0) -> 0 | AT24: =HLOOKUP(AT$8,$E$8:$AP$230,$B24,0)/HLOOKUP(AT$8,$E$8:$AN$230,$B11,0) -> 0 | AV24: =IFERROR(POWER(INDEX($E24:$AN24,AV$5)/INDEX($E24:$AN24,AV$4),1/AV$6)-1,) -> 0 | AW24: =IFERROR(POWER(INDEX($E24:$AN24,AW$5)/INDEX($E24:$AN24,AW$4),1/AW$6)-1,) -> 0 | AX24: =IFERROR(POWER(INDEX($E24:$AN24,AX$5)/INDEX($E24:$AN24,AX$4),1/AX$6)-1,) -> 0 | AY24: =IFERROR(POWER(INDEX($E24:$AN24,AY$5)/INDEX($E24:$AN24,AY$4),1/AY$6)-1,) -> 0 | AZ24: =IFERROR(POWER(INDEX($E24:$AN24,AZ$5)/INDEX($E24:$AN24,AZ$4),1/AZ$6)-1,) -> 0 | BA24: =IFERROR(POWER(INDEX($E24:$AN24,BA$5)/INDEX($E24:$AN24,BA$4),1/BA$6)-1,) -> 0
A25: =ADDRESS(MATCH($D10,'2021'!$A$1:$A$86,0),MATCH($D25,'2021'!$A$1:$AQ$1,0)) -> $P$48 | B25: =B24+1 -> 18 | D25: Gasoline | E25: =INDIRECT("'"&E$8&"'!"&$A25)*VLOOKUP($D$8,Tables!$C$1:$D$3,2,0) -> 33320.484 | F25: =INDIRECT("'"&F$8&"'!"&$A25)*VLOOKUP($D$8,Tables!$C$1:$D$3,2,0) -> 34438.177 | G25: =INDIRECT("'"&G$8&"'!"&$A25)*VLOOKUP($D$8,Tables!$C$1:$D$3,2,0) -> 35000.306 | H25: =INDIRECT("'"&H$8&"'!"&$A25)*VLOOKUP($D$8,Tables!$C$1:$D$3,2,0) -> 35956.856 | I25: =INDIRECT("'"&I$8&"'!"&$A25)*VLOOKUP($D$8,Tables!$C$1:$D$3,2,0) -> 37617.257 | J25: =INDIRECT("'"&J$8&"'!"&$A25)*VLOOKUP($D$8,Tables!$C$1:$D$3,2,0) -> 39471.401 | K25: =INDIRECT("'"&K$8&"'!"&$A25)*VLOOKUP($D$8,Tables!$C$1:$D$3,2,0) -> 42058.284 | L25: =INDIRECT("'"&L$8&"'!"&$A25)*VLOOKUP($D$8,Tables!$C$1:$D$3,2,0) -> 45037.068 | ... AM25: =INDIRECT("'"&AM$8&"'!"&$A25)*VLOOKUP($D$8,Tables!$C$1:$D$3,2,0) -> 28383.159 | AP25: =HLOOKUP(AP$8,$E$8:$AP$230,$B25,0)/HLOOKUP(AP$8,$E$8:$AN$230,$B11,0) -> 0.85925633 | AQ25: =HLOOKUP(AQ$8,$E$8:$AP$230,$B25,0)/HLOOKUP(AQ$8,$E$8:$AN$230,$B11,0) -> 0.80137047 | AR25: =HLOOKUP(AR$8,$E$8:$AP$230,$B25,0)/HLOOKUP(AR$8,$E$8:$AN$230,$B11,0) -> 0.63790281 | AS25: =HLOOKUP(AS$8,$E$8:$AP$230,$B25,0)/HLOOKUP(AS$8,$E$8:$AN$230,$B11,0) -> 0.31627225 | AT25: =HLOOKUP(AT$8,$E$8:$AP$230,$B25,0)/HLOOKUP(AT$8,$E$8:$AN$230,$B11,0) -> 0.79775471 | AV25: =IFERROR(POWER(INDEX($E25:$AN25,AV$5)/INDEX($E25:$AN25,AV$4),1/AV$6)-1,) -> -0.0082834424 | AW25: =IFERROR(POWER(INDEX($E25:$AN25,AW$5)/INDEX($E25:$AN25,AW$4),1/AW$6)-1,) -> 0.047800061 | AX25: =IFERROR(POWER(INDEX($E25:$AN25,AX$5)/INDEX($E25:$AN25,AX$4),1/AX$6)-1,) -> 0.021979339 | AY25: =IFERROR(POWER(INDEX($E25:$AN25,AY$5)/INDEX($E25:$AN25,AY$4),1/AY$6)-1,) -> -0.069740168 | AZ25: =IFERROR(POWER(INDEX($E25:$AN25,AZ$5)/INDEX($E25:$AN25,AZ$4),1/AZ$6)-1,) -> -0.099423346 | BA25: =IFERROR(POWER(INDEX($E25:$AN25,BA$5)/INDEX($E25:$AN25,BA$4),1/BA$6)-1,) -> -0.026571897
A26: =ADDRESS(MATCH($D10,'2021'!$A$1:$A$86,0),MATCH($D26,'2021'!$A$1:$AQ$1,0)) -> $Q$48 | B26: =B25+1 -> 19 | D26: Kerosene | E26: =INDIRECT("'"&E$8&"'!"&$A26)*VLOOKUP($D$8,Tables!$C$1:$D$3,2,0) -> 0 | F26: =INDIRECT("'"&F$8&"'!"&$A26)*VLOOKUP($D$8,Tables!$C$1:$D$3,2,0) -> 0 | G26: =INDIRECT("'"&G$8&"'!"&$A26)*VLOOKUP($D$8,Tables!$C$1:$D$3,2,0) -> 0 | H26: =INDIRECT("'"&H$8&"'!"&$A26)*VLOOKUP($D$8,Tables!$C$1:$D$3,2,0) -> 0 | I26: =INDIRECT("'"&I$8&"'!"&$A26)*VLOOKUP($D$8,Tables!$C$1:$D$3,2,0) -> 0 | J26: =INDIRECT("'"&J$8&"'!"&$A26)*VLOOKUP($D$8,Tables!$C$1:$D$3,2,0) -> 0 | K26: =INDIRECT("'"&K$8&"'!"&$A26)*VLOOKUP($D$8,Tables!$C$1:$D$3,2,0) -> 0 | L26: =INDIRECT("'"&L$8&"'!"&$A26)*VLOOKUP($D$8,Tables!$C$1:$D$3,2,0) -> 0 | ... AM26: =INDIRECT("'"&AM$8&"'!"&$A26)*VLOOKUP($D$8,Tables!$C$1:$D$3,2,0) -> 0 | AP26: =HLOOKUP(AP$8,$E$8:$AP$230,$B26,0)/HLOOKUP(AP$8,$E$8:$AN$230,$B11,0) -> 0 | AQ26: =HLOOKUP(AQ$8,$E$8:$AP$230,$B26,0)/HLOOKUP(AQ$8,$E$8:$AN$230,$B11,0) -> 0 | AR26: =HLOOKUP(AR$8,$E$8:$AP$230,$B26,0)/HLOOKUP(AR$8,$E$8:$AN$230,$B11,0) -> 0 | AS26: =HLOOKUP(AS$8,$E$8:$AP$230,$B26,0)/HLOOKUP(AS$8,$E$8:$AN$230,$B11,0) -> 0 | AT26: =HLOOKUP(AT$8,$E$8:$AP$230,$B26,0)/HLOOKUP(AT$8,$E$8:$AN$230,$B11,0) -> 0 | AV26: =IFERROR(POWER(INDEX($E26:$AN26,AV$5)/INDEX($E26:$AN26,AV$4),1/AV$6)-1,) -> 0 | AW26: =IFERROR(POWER(INDEX($E26:$AN26,AW$5)/INDEX($E26:$AN26,AW$4),1/AW$6)-1,) -> 0 | AX26: =IFERROR(POWER(INDEX($E26:$AN26,AX$5)/INDEX($E26:$AN26,AX$4),1/AX$6)-1,) -> 0 | AY26: =IFERROR(POWER(INDEX($E26:$AN26,AY$5)/INDEX($E26:$AN26,AY$4),1/AY$6)-1,) -> 0 | AZ26: =IFERROR(POWER(INDEX($E26:$AN26,AZ$5)/INDEX($E26:$AN26,AZ$4),1/AZ$6)-1,) -> 0 | BA26: =IFERROR(POWER(INDEX($E26:$AN26,BA$5)/INDEX($E26:$AN26,BA$4),1/BA$6)-1,) -> 0
A27: =ADDRESS(MATCH($D10,'2021'!$A$1:$A$86,0),MATCH($D27,'2021'!$A$1:$AQ$1,0)) -> $R$48 | B27: =B26+1 -> 20 | D27: Jet Kerosene | E27: =INDIRECT("'"&E$8&"'!"&$A27)*VLOOKUP($D$8,Tables!$C$1:$D$3,2,0) -> 0 | F27: =INDIRECT("'"&F$8&"'!"&$A27)*VLOOKUP($D$8,Tables!$C$1:$D$3,2,0) -> 0 | G27: =INDIRECT("'"&G$8&"'!"&$A27)*VLOOKUP($D$8,Tables!$C$1:$D$3,2,0) -> 0 | H27: =INDIRECT("'"&H$8&"'!"&$A27)*VLOOKUP($D$8,Tables!$C$1:$D$3,2,0) -> 0 | I27: =INDIRECT("'"&I$8&"'!"&$A27)*VLOOKUP($D$8,Tables!$C$1:$D$3,2,0) -> 0 | J27: =INDIRECT("'"&J$8&"'!"&$A27)*VLOOKUP($D$8,Tables!$C$1:$D$3,2,0) -> 0 | K27: =INDIRECT("'"&K$8&"'!"&$A27)*VLOOKUP($D$8,Tables!$C$1:$D$3,2,0) -> 0 | L27: =INDIRECT("'"&L$8&"'!"&$A27)*VLOOKUP($D$8,Tables!$C$1:$D$3,2,0) -> 0 | ... AM27: =INDIRECT("'"&AM$8&"'!"&$A27)*VLOOKUP($D$8,Tables!$C$1:$D$3,2,0) -> 0 | AP27: =HLOOKUP(AP$8,$E$8:$AP$230,$B27,0)/HLOOKUP(AP$8,$E$8:$AN$230,$B11,0) -> 0 | AQ27: =HLOOKUP(AQ$8,$E$8:$AP$230,$B27,0)/HLOOKUP(AQ$8,$E$8:$AN$230,$B11,0) -> 0 | AR27: =HLOOKUP(AR$8,$E$8:$AP$230,$B27,0)/HLOOKUP(AR$8,$E$8:$AN$230,$B11,0) -> 0 | AS27: =HLOOKUP(AS$8,$E$8:$AP$230,$B27,0)/HLOOKUP(AS$8,$E$8:$AN$230,$B11,0) -> 0 | AT27: =HLOOKUP(AT$8,$E$8:$AP$230,$B27,0)/HLOOKUP(AT$8,$E$8:$AN$230,$B11,0) -> 0 | AV27: =IFERROR(POWER(INDEX($E27:$AN27,AV$5)/INDEX($E27:$AN27,AV$4),1/AV$6)-1,) -> 0 | AW27: =IFERROR(POWER(INDEX($E27:$AN27,AW$5)/INDEX($E27:$AN27,AW$4),1/AW$6)-1,) -> 0 | AX27: =IFERROR(POWER(INDEX($E27:$AN27,AX$5)/INDEX($E27:$AN27,AX$4),1/AX$6)-1,) -> 0 | AY27: =IFERROR(POWER(INDEX($E27:$AN27,AY$5)/INDEX($E27:$AN27,AY$4),1/AY$6)-1,) -> 0 | AZ27: =IFERROR(POWER(INDEX($E27:$AN27,AZ$5)/INDEX($E27:$AN27,AZ$4),1/AZ$6)-1,) -> 0 | BA27: =IFERROR(POWER(INDEX($E27:$AN27,BA$5)/INDEX($E27:$AN27,BA$4),1/BA$6)-1,) -> 0
A28: =ADDRESS(MATCH($D10,'2021'!$A$1:$A$86,0),MATCH($D28,'2021'!$A$1:$AQ$1,0)) -> $S$48 | B28: =B27+1 -> 21 | D28: Fueloil | E28: =INDIRECT("'"&E$8&"'!"&$A28)*VLOOKUP($D$8,Tables!$C$1:$D$3,2,0) -> 0 | F28: =INDIRECT("'"&F$8&"'!"&$A28)*VLOOKUP($D$8,Tables!$C$1:$D$3,2,0) -> 0 | G28: =INDIRECT("'"&G$8&"'!"&$A28)*VLOOKUP($D$8,Tables!$C$1:$D$3,2,0) -> 0 | H28: =INDIRECT("'"&H$8&"'!"&$A28)*VLOOKUP($D$8,Tables!$C$1:$D$3,2,0) -> 0 | I28: =INDIRECT("'"&I$8&"'!"&$A28)*VLOOKUP($D$8,Tables!$C$1:$D$3,2,0) -> 0 | J28: =INDIRECT("'"&J$8&"'!"&$A28)*VLOOKUP($D$8,Tables!$C$1:$D$3,2,0) -> 0 | K28: =INDIRECT("'"&K$8&"'!"&$A28)*VLOOKUP($D$8,Tables!$C$1:$D$3,2,0) -> 0 | L28: =INDIRECT("'"&L$8&"'!"&$A28)*VLOOKUP($D$8,Tables!$C$1:$D$3,2,0) -> 0 | ... AM28: =INDIRECT("'"&AM$8&"'!"&$A28)*VLOOKUP($D$8,Tables!$C$1:$D$3,2,0) -> 0 | AP28: =HLOOKUP(AP$8,$E$8:$AP$230,$B28,0)/HLOOKUP(AP$8,$E$8:$AN$230,$B11,0) -> 0 | AQ28: =HLOOKUP(AQ$8,$E$8:$AP$230,$B28,0)/HLOOKUP(AQ$8,$E$8:$AN$230,$B11,0) -> 0 | AR28: =HLOOKUP(AR$8,$E$8:$AP$230,$B28,0)/HLOOKUP(AR$8,$E$8:$AN$230,$B11,0) -> 0 | AS28: =HLOOKUP(AS$8,$E$8:$AP$230,$B28,0)/HLOOKUP(AS$8,$E$8:$AN$230,$B11,0) -> 0 | AT28: =HLOOKUP(AT$8,$E$8:$AP$230,$B28,0)/HLOOKUP(AT$8,$E$8:$AN$230,$B11,0) -> 0 | AV28: =IFERROR(POWER(INDEX($E28:$AN28,AV$5)/INDEX($E28:$AN28,AV$4),1/AV$6)-1,) -> 0 | AW28: =IFERROR(POWER(INDEX($E28:$AN28,AW$5)/INDEX($E28:$AN28,AW$4),1/AW$6)-1,) -> 0 | AX28: =IFERROR(POWER(INDEX($E28:$AN28,AX$5)/INDEX($E28:$AN28,AX$4),1/AX$6)-1,) -> 0 | AY28: =IFERROR(POWER(INDEX($E28:$AN28,AY$5)/INDEX($E28:$AN28,AY$4),1/AY$6)-1,) -> 0 | AZ28: =IFERROR(POWER(INDEX($E28:$AN28,AZ$5)/INDEX($E28:$AN28,AZ$4),1/AZ$6)-1,) -> 0 | BA28: =IFERROR(POWER(INDEX($E28:$AN28,BA$5)/INDEX($E28:$AN28,BA$4),1/BA$6)-1,) -> 0
A29: =ADDRESS(MATCH($D10,'2021'!$A$1:$A$86,0),MATCH($D29,'2021'!$A$1:$AQ$1,0)) -> $T$48 | B29: =B28+1 -> 22 | D29: LPG | E29: =INDIRECT("'"&E$8&"'!"&$A29)*VLOOKUP($D$8,Tables!$C$1:$D$3,2,0) -> 290.96329 | F29: =INDIRECT("'"&F$8&"'!"&$A29)*VLOOKUP($D$8,Tables!$C$1:$D$3,2,0) -> 328.08364 | G29: =INDIRECT("'"&G$8&"'!"&$A29)*VLOOKUP($D$8,Tables!$C$1:$D$3,2,0) -> 332.04076 | H29: =INDIRECT("'"&H$8&"'!"&$A29)*VLOOKUP($D$8,Tables!$C$1:$D$3,2,0) -> 319.70986 | I29: =INDIRECT("'"&I$8&"'!"&$A29)*VLOOKUP($D$8,Tables!$C$1:$D$3,2,0) -> 299.89872 | J29: =INDIRECT("'"&J$8&"'!"&$A29)*VLOOKUP($D$8,Tables!$C$1:$D$3,2,0) -> 252.36221 | K29: =INDIRECT("'"&K$8&"'!"&$A29)*VLOOKUP($D$8,Tables!$C$1:$D$3,2,0) -> 197.85606 | L29: =INDIRECT("'"&L$8&"'!"&$A29)*VLOOKUP($D$8,Tables!$C$1:$D$3,2,0) -> 168.31806 | ... AM29: =INDIRECT("'"&AM$8&"'!"&$A29)*VLOOKUP($D$8,Tables!$C$1:$D$3,2,0) -> 30.708225 | AP29: =HLOOKUP(AP$8,$E$8:$AP$230,$B29,0)/HLOOKUP(AP$8,$E$8:$AN$230,$B11,0) -> 0.0075032536 | AQ29: =HLOOKUP(AQ$8,$E$8:$AP$230,$B29,0)/HLOOKUP(AQ$8,$E$8:$AN$230,$B11,0) -> 0.0051235988 | AR29: =HLOOKUP(AR$8,$E$8:$AP$230,$B29,0)/HLOOKUP(AR$8,$E$8:$AN$230,$B11,0) -> 0.00025569739 | AS29: =HLOOKUP(AS$8,$E$8:$AP$230,$B29,0)/HLOOKUP(AS$8,$E$8:$AN$230,$B11,0) -> 0.00055966038 | AT29: =HLOOKUP(AT$8,$E$8:$AP$230,$B29,0)/HLOOKUP(AT$8,$E$8:$AN$230,$B11,0) -> 0.0037529016 | AV29: =IFERROR(POWER(INDEX($E29:$AN29,AV$5)/INDEX($E29:$AN29,AV$4),1/AV$6)-1,) -> -0.044458423 | AW29: =IFERROR(POWER(INDEX($E29:$AN29,AW$5)/INDEX($E29:$AN29,AW$4),1/AW$6)-1,) -> -0.1094202 | AX29: =IFERROR(POWER(INDEX($E29:$AN29,AX$5)/INDEX($E29:$AN29,AX$4),1/AX$6)-1,) -> -0.10475448 | AY29: =IFERROR(POWER(INDEX($E29:$AN29,AY$5)/INDEX($E29:$AN29,AY$4),1/AY$6)-1,) -> 0.026690739 | AZ29: =IFERROR(POWER(INDEX($E29:$AN29,AZ$5)/INDEX($E29:$AN29,AZ$4),1/AZ$6)-1,) -> -0.10421642 | BA29: =IFERROR(POWER(INDEX($E29:$AN29,BA$5)/INDEX($E29:$AN29,BA$4),1/BA$6)-1,) -> -0.14417549
A30: =ADDRESS(MATCH($D10,'2021'!$A$1:$A$86,0),MATCH($D30,'2021'!$A$1:$AQ$1,0)) -> $U$48 | B30: =B29+1 -> 23 | D30: Gasoil / Diesel /DERV | E30: =INDIRECT("'"&E$8&"'!"&$A30)*VLOOKUP($D$8,Tables!$C$1:$D$3,2,0) -> 5166.8345 | F30: =INDIRECT("'"&F$8&"'!"&$A30)*VLOOKUP($D$8,Tables!$C$1:$D$3,2,0) -> 6319.888 | G30: =INDIRECT("'"&G$8&"'!"&$A30)*VLOOKUP($D$8,Tables!$C$1:$D$3,2,0) -> 7029.2588 | H30: =INDIRECT("'"&H$8&"'!"&$A30)*VLOOKUP($D$8,Tables!$C$1:$D$3,2,0) -> 7855.8369 | I30: =INDIRECT("'"&I$8&"'!"&$A30)*VLOOKUP($D$8,Tables!$C$1:$D$3,2,0) -> 8719.183 | J30: =INDIRECT("'"&J$8&"'!"&$A30)*VLOOKUP($D$8,Tables!$C$1:$D$3,2,0) -> 9531.1101 | K30: =INDIRECT("'"&K$8&"'!"&$A30)*VLOOKUP($D$8,Tables!$C$1:$D$3,2,0) -> 10464.682 | L30: =INDIRECT("'"&L$8&"'!"&$A30)*VLOOKUP($D$8,Tables!$C$1:$D$3,2,0) -> 11234.981 | ... AM30: =INDIRECT("'"&AM$8&"'!"&$A30)*VLOOKUP($D$8,Tables!$C$1:$D$3,2,0) -> 53648.487 | AP30: =HLOOKUP(AP$8,$E$8:$AP$230,$B30,0)/HLOOKUP(AP$8,$E$8:$AN$230,$B11,0) -> 0.13324042 | AQ30: =HLOOKUP(AQ$8,$E$8:$AP$230,$B30,0)/HLOOKUP(AQ$8,$E$8:$AN$230,$B11,0) -> 0.19350593 | AR30: =HLOOKUP(AR$8,$E$8:$AP$230,$B30,0)/HLOOKUP(AR$8,$E$8:$AN$230,$B11,0) -> 0.33812344 | AS30: =HLOOKUP(AS$8,$E$8:$AP$230,$B30,0)/HLOOKUP(AS$8,$E$8:$AN$230,$B11,0) -> 0.60321402 | AT30: =HLOOKUP(AT$8,$E$8:$AP$230,$B30,0)/HLOOKUP(AT$8,$E$8:$AN$230,$B11,0) -> 0.19849239 | AV30: =IFERROR(POWER(INDEX($E30:$AN30,AV$5)/INDEX($E30:$AN30,AV$4),1/AV$6)-1,) -> 0.075178296 | AW30: =IFERROR(POWER(INDEX($E30:$AN30,AW$5)/INDEX($E30:$AN30,AW$4),1/AW$6)-1,) -> 0.08945357 | AX30: =IFERROR(POWER(INDEX($E30:$AN30,AX$5)/INDEX($E30:$AN30,AX$4),1/AX$6)-1,) -> 0.088665283 | AY30: =IFERROR(POWER(INDEX($E30:$AN30,AY$5)/INDEX($E30:$AN30,AY$4),1/AY$6)-1,) -> 0.11098352 | AZ30: =IFERROR(POWER(INDEX($E30:$AN30,AZ$5)/INDEX($E30:$AN30,AZ$4),1/AZ$6)-1,) -> 0.045025385 | BA30: =IFERROR(POWER(INDEX($E30:$AN30,BA$5)/INDEX($E30:$AN30,BA$4),1/BA$6)-1,) -> 0.0067700374
A31: =ADDRESS(MATCH($D10,'2021'!$A$1:$A$86,0),MATCH($D31,'2021'!$A$1:$AQ$1,0)) -> $V$48 | B31: =B30+1 -> 24 | D31: Petroleum Coke | E31: =INDIRECT("'"&E$8&"'!"&$A31)*VLOOKUP($D$8,Tables!$C$1:$D$3,2,0) -> 0 | F31: =INDIRECT("'"&F$8&"'!"&$A31)*VLOOKUP($D$8,Tables!$C$1:$D$3,2,0) -> 0 | G31: =INDIRECT("'"&G$8&"'!"&$A31)*VLOOKUP($D$8,Tables!$C$1:$D$3,2,0) -> 0 | H31: =INDIRECT("'"&H$8&"'!"&$A31)*VLOOKUP($D$8,Tables!$C$1:$D$3,2,0) -> 0 | I31: =INDIRECT("'"&I$8&"'!"&$A31)*VLOOKUP($D$8,Tables!$C$1:$D$3,2,0) -> 0 | J31: =INDIRECT("'"&J$8&"'!"&$A31)*VLOOKUP($D$8,Tables!$C$1:$D$3,2,0) -> 0 | K31: =INDIRECT("'"&K$8&"'!"&$A31)*VLOOKUP($D$8,Tables!$C$1:$D$3,2,0) -> 0 | L31: =INDIRECT("'"&L$8&"'!"&$A31)*VLOOKUP($D$8,Tables!$C$1:$D$3,2,0) -> 0 | ... AM31: =INDIRECT("'"&AM$8&"'!"&$A31)*VLOOKUP($D$8,Tables!$C$1:$D$3,2,0) -> 0 | AP31: =HLOOKUP(AP$8,$E$8:$AP$230,$B31,0)/HLOOKUP(AP$8,$E$8:$AN$230,$B11,0) -> 0 | AQ31: =HLOOKUP(AQ$8,$E$8:$AP$230,$B31,0)/HLOOKUP(AQ$8,$E$8:$AN$230,$B11,0) -> 0 | AR31: =HLOOKUP(AR$8,$E$8:$AP$230,$B31,0)/HLOOKUP(AR$8,$E$8:$AN$230,$B11,0) -> 0 | AS31: =HLOOKUP(AS$8,$E$8:$AP$230,$B31,0)/HLOOKUP(AS$8,$E$8:$AN$230,$B11,0) -> 0 | AT31: =HLOOKUP(AT$8,$E$8:$AP$230,$B31,0)/HLOOKUP(AT$8,$E$8:$AN$230,$B11,0) -> 0 | AV31: =IFERROR(POWER(INDEX($E31:$AN31,AV$5)/INDEX($E31:$AN31,AV$4),1/AV$6)-1,) -> 0 | AW31: =IFERROR(POWER(INDEX($E31:$AN31,AW$5)/INDEX($E31:$AN31,AW$4),1/AW$6)-1,) -> 0 | AX31: =IFERROR(POWER(INDEX($E31:$AN31,AX$5)/INDEX($E31:$AN31,AX$4),1/AX$6)-1,) -> 0 | AY31: =IFERROR(POWER(INDEX($E31:$AN31,AY$5)/INDEX($E31:$AN31,AY$4),1/AY$6)-1,) -> 0 | AZ31: =IFERROR(POWER(INDEX($E31:$AN31,AZ$5)/INDEX($E31:$AN31,AZ$4),1/AZ$6)-1,) -> 0 | BA31: =IFERROR(POWER(INDEX($E31:$AN31,BA$5)/INDEX($E31:$AN31,BA$4),1/BA$6)-1,) -> 0
A32: =ADDRESS(MATCH($D10,'2021'!$A$1:$A$86,0),MATCH($D32,'2021'!$A$1:$AQ$1,0)) -> $W$48 | B32: =B31+1 -> 25 | D32: Naphta | E32: =INDIRECT("'"&E$8&"'!"&$A32)*VLOOKUP($D$8,Tables!$C$1:$D$3,2,0) -> 0 | F32: =INDIRECT("'"&F$8&"'!"&$A32)*VLOOKUP($D$8,Tables!$C$1:$D$3,2,0) -> 0 | G32: =INDIRECT("'"&G$8&"'!"&$A32)*VLOOKUP($D$8,Tables!$C$1:$D$3,2,0) -> 0 | H32: =INDIRECT("'"&H$8&"'!"&$A32)*VLOOKUP($D$8,Tables!$C$1:$D$3,2,0) -> 0 | I32: =INDIRECT("'"&I$8&"'!"&$A32)*VLOOKUP($D$8,Tables!$C$1:$D$3,2,0) -> 0 | J32: =INDIRECT("'"&J$8&"'!"&$A32)*VLOOKUP($D$8,Tables!$C$1:$D$3,2,0) -> 0 | K32: =INDIRECT("'"&K$8&"'!"&$A32)*VLOOKUP($D$8,Tables!$C$1:$D$3,2,0) -> 0 | L32: =INDIRECT("'"&L$8&"'!"&$A32)*VLOOKUP($D$8,Tables!$C$1:$D$3,2,0) -> 0 | ... AM32: =INDIRECT("'"&AM$8&"'!"&$A32)*VLOOKUP($D$8,Tables!$C$1:$D$3,2,0) -> 0 | AP32: =HLOOKUP(AP$8,$E$8:$AP$230,$B32,0)/HLOOKUP(AP$8,$E$8:$AN$230,$B11,0) -> 0 | AQ32: =HLOOKUP(AQ$8,$E$8:$AP$230,$B32,0)/HLOOKUP(AQ$8,$E$8:$AN$230,$B11,0) -> 0 | AR32: =HLOOKUP(AR$8,$E$8:$AP$230,$B32,0)/HLOOKUP(AR$8,$E$8:$AN$230,$B11,0) -> 0 | AS32: =HLOOKUP(AS$8,$E$8:$AP$230,$B32,0)/HLOOKUP(AS$8,$E$8:$AN$230,$B11,0) -> 0 | AT32: =HLOOKUP(AT$8,$E$8:$AP$230,$B32,0)/HLOOKUP(AT$8,$E$8:$AN$230,$B11,0) -> 0 | AV32: =IFERROR(POWER(INDEX($E32:$AN32,AV$5)/INDEX($E32:$AN32,AV$4),1/AV$6)-1,) -> 0 | AW32: =IFERROR(POWER(INDEX($E32:$AN32,AW$5)/INDEX($E32:$AN32,AW$4),1/AW$6)-1,) -> 0 | AX32: =IFERROR(POWER(INDEX($E32:$AN32,AX$5)/INDEX($E32:$AN32,AX$4),1/AX$6)-1,) -> 0 | AY32: =IFERROR(POWER(INDEX($E32:$AN32,AY$5)/INDEX($E32:$AN32,AY$4),1/AY$6)-1,) -> 0 | AZ32: =IFERROR(POWER(INDEX($E32:$AN32,AZ$5)/INDEX($E32:$AN32,AZ$4),1/AZ$6)-1,) -> 0 | BA32: =IFERROR(POWER(INDEX($E32:$AN32,BA$5)/INDEX($E32:$AN32,BA$4),1/BA$6)-1,) -> 0
A33: =ADDRESS(MATCH($D10,'2021'!$A$1:$A$86,0),MATCH($D33,'2021'!$A$1:$AQ$1,0)) -> $X$48 | B33: =B32+1 -> 26 | D33: Bitumen | E33: =INDIRECT("'"&E$8&"'!"&$A33)*VLOOKUP($D$8,Tables!$C$1:$D$3,2,0) -> 0 | F33: =INDIRECT("'"&F$8&"'!"&$A33)*VLOOKUP($D$8,Tables!$C$1:$D$3,2,0) -> 0 | G33: =INDIRECT("'"&G$8&"'!"&$A33)*VLOOKUP($D$8,Tables!$C$1:$D$3,2,0) -> 0 | H33: =INDIRECT("'"&H$8&"'!"&$A33)*VLOOKUP($D$8,Tables!$C$1:$D$3,2,0) -> 0 | I33: =INDIRECT("'"&I$8&"'!"&$A33)*VLOOKUP($D$8,Tables!$C$1:$D$3,2,0) -> 0 | J33: =INDIRECT("'"&J$8&"'!"&$A33)*VLOOKUP($D$8,Tables!$C$1:$D$3,2,0) -> 0 | K33: =INDIRECT("'"&K$8&"'!"&$A33)*VLOOKUP($D$8,Tables!$C$1:$D$3,2,0) -> 0 | L33: =INDIRECT("'"&L$8&"'!"&$A33)*VLOOKUP($D$8,Tables!$C$1:$D$3,2,0) -> 0 | ... AM33: =INDIRECT("'"&AM$8&"'!"&$A33)*VLOOKUP($D$8,Tables!$C$1:$D$3,2,0) -> 0 | AP33: =HLOOKUP(AP$8,$E$8:$AP$230,$B33,0)/HLOOKUP(AP$8,$E$8:$AN$230,$B11,0) -> 0 | AQ33: =HLOOKUP(AQ$8,$E$8:$AP$230,$B33,0)/HLOOKUP(AQ$8,$E$8:$AN$230,$B11,0) -> 0 | AR33: =HLOOKUP(AR$8,$E$8:$AP$230,$B33,0)/HLOOKUP(AR$8,$E$8:$AN$230,$B11,0) -> 0 | AS33: =HLOOKUP(AS$8,$E$8:$AP$230,$B33,0)/HLOOKUP(AS$8,$E$8:$AN$230,$B11,0) -> 0 | AT33: =HLOOKUP(AT$8,$E$8:$AP$230,$B33,0)/HLOOKUP(AT$8,$E$8:$AN$230,$B11,0) -> 0 | AV33: =IFERROR(POWER(INDEX($E33:$AN33,AV$5)/INDEX($E33:$AN33,AV$4),1/AV$6)-1,) -> 0 | AW33: =IFERROR(POWER(INDEX($E33:$AN33,AW$5)/INDEX($E33:$AN33,AW$4),1/AW$6)-1,) -> 0 | AX33: =IFERROR(POWER(INDEX($E33:$AN33,AX$5)/INDEX($E33:$AN33,AX$4),1/AX$6)-1,) -> 0 | AY33: =IFERROR(POWER(INDEX($E33:$AN33,AY$5)/INDEX($E33:$AN33,AY$4),1/AY$6)-1,) -> 0 | AZ33: =IFERROR(POWER(INDEX($E33:$AN33,AZ$5)/INDEX($E33:$AN33,AZ$4),1/AZ$6)-1,) -> 0 | BA33: =IFERROR(POWER(INDEX($E33:$AN33,BA$5)/INDEX($E33:$AN33,BA$4),1/BA$6)-1,) -> 0
A34: =ADDRESS(MATCH($D10,'2021'!$A$1:$A$86,0),MATCH($D34,'2021'!$A$1:$AQ$1,0)) -> $Y$48 | B34: =B33+1 -> 27 | D34: White Spirit | E34: =INDIRECT("'"&E$8&"'!"&$A34)*VLOOKUP($D$8,Tables!$C$1:$D$3,2,0) -> 0 | F34: =INDIRECT("'"&F$8&"'!"&$A34)*VLOOKUP($D$8,Tables!$C$1:$D$3,2,0) -> 0 | G34: =INDIRECT("'"&G$8&"'!"&$A34)*VLOOKUP($D$8,Tables!$C$1:$D$3,2,0) -> 0 | H34: =INDIRECT("'"&H$8&"'!"&$A34)*VLOOKUP($D$8,Tables!$C$1:$D$3,2,0) -> 0 | I34: =INDIRECT("'"&I$8&"'!"&$A34)*VLOOKUP($D$8,Tables!$C$1:$D$3,2,0) -> 0 | J34: =INDIRECT("'"&J$8&"'!"&$A34)*VLOOKUP($D$8,Tables!$C$1:$D$3,2,0) -> 0 | K34: =INDIRECT("'"&K$8&"'!"&$A34)*VLOOKUP($D$8,Tables!$C$1:$D$3,2,0) -> 0 | L34: =INDIRECT("'"&L$8&"'!"&$A34)*VLOOKUP($D$8,Tables!$C$1:$D$3,2,0) -> 0 | ... AM34: =INDIRECT("'"&AM$8&"'!"&$A34)*VLOOKUP($D$8,Tables!$C$1:$D$3,2,0) -> 0 | AP34: =HLOOKUP(AP$8,$E$8:$AP$230,$B34,0)/HLOOKUP(AP$8,$E$8:$AN$230,$B11,0) -> 0 | AQ34: =HLOOKUP(AQ$8,$E$8:$AP$230,$B34,0)/HLOOKUP(AQ$8,$E$8:$AN$230,$B11,0) -> 0 | AR34: =HLOOKUP(AR$8,$E$8:$AP$230,$B34,0)/HLOOKUP(AR$8,$E$8:$AN$230,$B11,0) -> 0 | AS34: =HLOOKUP(AS$8,$E$8:$AP$230,$B34,0)/HLOOKUP(AS$8,$E$8:$AN$230,$B11,0) -> 0 | AT34: =HLOOKUP(AT$8,$E$8:$AP$230,$B34,0)/HLOOKUP(AT$8,$E$8:$AN$230,$B11,0) -> 0 | AV34: =IFERROR(POWER(INDEX($E34:$AN34,AV$5)/INDEX($E34:$AN34,AV$4),1/AV$6)-1,) -> 0 | AW34: =IFERROR(POWER(INDEX($E34:$AN34,AW$5)/INDEX($E34:$AN34,AW$4),1/AW$6)-1,) -> 0 | AX34: =IFERROR(POWER(INDEX($E34:$AN34,AX$5)/INDEX($E34:$AN34,AX$4),1/AX$6)-1,) -> 0 | AY34: =IFERROR(POWER(INDEX($E34:$AN34,AY$5)/INDEX($E34:$AN34,AY$4),1/AY$6)-1,) -> 0 | AZ34: =IFERROR(POWER(INDEX($E34:$AN34,AZ$5)/INDEX($E34:$AN34,AZ$4),1/AZ$6)-1,) -> 0 | BA34: =IFERROR(POWER(INDEX($E34:$AN34,BA$5)/INDEX($E34:$AN34,BA$4),1/BA$6)-1,) -> 0
A35: =ADDRESS(MATCH($D10,'2021'!$A$1:$A$86,0),MATCH($D35,'2021'!$A$1:$AQ$1,0)) -> $Z$48 | B35: =B34+1 -> 28 | D35: Lubricants | E35: =INDIRECT("'"&E$8&"'!"&$A35)*VLOOKUP($D$8,Tables!$C$1:$D$3,2,0) -> 0 | F35: =INDIRECT("'"&F$8&"'!"&$A35)*VLOOKUP($D$8,Tables!$C$1:$D$3,2,0) -> 0 | G35: =INDIRECT("'"&G$8&"'!"&$A35)*VLOOKUP($D$8,Tables!$C$1:$D$3,2,0) -> 0 | H35: =INDIRECT("'"&H$8&"'!"&$A35)*VLOOKUP($D$8,Tables!$C$1:$D$3,2,0) -> 0 | I35: =INDIRECT("'"&I$8&"'!"&$A35)*VLOOKUP($D$8,Tables!$C$1:$D$3,2,0) -> 0 | J35: =INDIRECT("'"&J$8&"'!"&$A35)*VLOOKUP($D$8,Tables!$C$1:$D$3,2,0) -> 0 | K35: =INDIRECT("'"&K$8&"'!"&$A35)*VLOOKUP($D$8,Tables!$C$1:$D$3,2,0) -> 0 | L35: =INDIRECT("'"&L$8&"'!"&$A35)*VLOOKUP($D$8,Tables!$C$1:$D$3,2,0) -> 0 | ... AM35: =INDIRECT("'"&AM$8&"'!"&$A35)*VLOOKUP($D$8,Tables!$C$1:$D$3,2,0) -> 0 | AP35: =HLOOKUP(AP$8,$E$8:$AP$230,$B35,0)/HLOOKUP(AP$8,$E$8:$AN$230,$B11,0) -> 0 | AQ35: =HLOOKUP(AQ$8,$E$8:$AP$230,$B35,0)/HLOOKUP(AQ$8,$E$8:$AN$230,$B11,0) -> 0 | AR35: =HLOOKUP(AR$8,$E$8:$AP$230,$B35,0)/HLOOKUP(AR$8,$E$8:$AN$230,$B11,0) -> 0 | AS35: =HLOOKUP(AS$8,$E$8:$AP$230,$B35,0)/HLOOKUP(AS$8,$E$8:$AN$230,$B11,0) -> 0 | AT35: =HLOOKUP(AT$8,$E$8:$AP$230,$B35,0)/HLOOKUP(AT$8,$E$8:$AN$230,$B11,0) -> 0 | AV35: =IFERROR(POWER(INDEX($E35:$AN35,AV$5)/INDEX($E35:$AN35,AV$4),1/AV$6)-1,) -> 0 | AW35: =IFERROR(POWER(INDEX($E35:$AN35,AW$5)/INDEX($E35:$AN35,AW$4),1/AW$6)-1,) -> 0 | AX35: =IFERROR(POWER(INDEX($E35:$AN35,AX$5)/INDEX($E35:$AN35,AX$4),1/AX$6)-1,) -> 0 | AY35: =IFERROR(POWER(INDEX($E35:$AN35,AY$5)/INDEX($E35:$AN35,AY$4),1/AY$6)-1,) -> 0 | AZ35: =IFERROR(POWER(INDEX($E35:$AN35,AZ$5)/INDEX($E35:$AN35,AZ$4),1/AZ$6)-1,) -> 0 | BA35: =IFERROR(POWER(INDEX($E35:$AN35,BA$5)/INDEX($E35:$AN35,BA$4),1/BA$6)-1,) -> 0
A36: =ADDRESS(MATCH($D10,'2021'!$A$1:$A$86,0),MATCH($D36,'2021'!$A$1:$AQ$1,0)) -> $AA$48 | B36: =B35+1 -> 29 | D36: Natural Gas | E36: =INDIRECT("'"&E$8&"'!"&$A36)*VLOOKUP($D$8,Tables!$C$1:$D$3,2,0) -> 0 | F36: =INDIRECT("'"&F$8&"'!"&$A36)*VLOOKUP($D$8,Tables!$C$1:$D$3,2,0) -> 0 | G36: =INDIRECT("'"&G$8&"'!"&$A36)*VLOOKUP($D$8,Tables!$C$1:$D$3,2,0) -> 0 | H36: =INDIRECT("'"&H$8&"'!"&$A36)*VLOOKUP($D$8,Tables!$C$1:$D$3,2,0) -> 0 | I36: =INDIRECT("'"&I$8&"'!"&$A36)*VLOOKUP($D$8,Tables!$C$1:$D$3,2,0) -> 0 | J36: =INDIRECT("'"&J$8&"'!"&$A36)*VLOOKUP($D$8,Tables!$C$1:$D$3,2,0) -> 0 | K36: =INDIRECT("'"&K$8&"'!"&$A36)*VLOOKUP($D$8,Tables!$C$1:$D$3,2,0) -> 0 | L36: =INDIRECT("'"&L$8&"'!"&$A36)*VLOOKUP($D$8,Tables!$C$1:$D$3,2,0) -> 0 | ... AM36: =INDIRECT("'"&AM$8&"'!"&$A36)*VLOOKUP($D$8,Tables!$C$1:$D$3,2,0) -> 0 | AP36: =HLOOKUP(AP$8,$E$8:$AP$230,$B36,0)/HLOOKUP(AP$8,$E$8:$AN$230,$B11,0) -> 0 | AQ36: =HLOOKUP(AQ$8,$E$8:$AP$230,$B36,0)/HLOOKUP(AQ$8,$E$8:$AN$230,$B11,0) -> 0 | AR36: =HLOOKUP(AR$8,$E$8:$AP$230,$B36,0)/HLOOKUP(AR$8,$E$8:$AN$230,$B11,0) -> 0 | AS36: =HLOOKUP(AS$8,$E$8:$AP$230,$B36,0)/HLOOKUP(AS$8,$E$8:$AN$230,$B11,0) -> 0 | AT36: =HLOOKUP(AT$8,$E$8:$AP$230,$B36,0)/HLOOKUP(AT$8,$E$8:$AN$230,$B11,0) -> 0 | AV36: =IFERROR(POWER(INDEX($E36:$AN36,AV$5)/INDEX($E36:$AN36,AV$4),1/AV$6)-1,) -> 0 | AW36: =IFERROR(POWER(INDEX($E36:$AN36,AW$5)/INDEX($E36:$AN36,AW$4),1/AW$6)-1,) -> 0 | AX36: =IFERROR(POWER(INDEX($E36:$AN36,AX$5)/INDEX($E36:$AN36,AX$4),1/AX$6)-1,) -> 0 | AY36: =IFERROR(POWER(INDEX($E36:$AN36,AY$5)/INDEX($E36:$AN36,AY$4),1/AY$6)-1,) -> 0 | AZ36: =IFERROR(POWER(INDEX($E36:$AN36,AZ$5)/INDEX($E36:$AN36,AZ$4),1/AZ$6)-1,) -> 0 | BA36: =IFERROR(POWER(INDEX($E36:$AN36,BA$5)/INDEX($E36:$AN36,BA$4),1/BA$6)-1,) -> 0
A37: =ADDRESS(MATCH($D10,'2021'!$A$1:$A$86,0),MATCH($D37,'2021'!$A$1:$AQ$1,0)) -> $AB$48 | B37: =B36+1 -> 30 | D37: Renewables | E37: =INDIRECT("'"&E$8&"'!"&$A37)*VLOOKUP($D$8,Tables!$C$1:$D$3,2,0) -> 0 | F37: =INDIRECT("'"&F$8&"'!"&$A37)*VLOOKUP($D$8,Tables!$C$1:$D$3,2,0) -> 0 | G37: =INDIRECT("'"&G$8&"'!"&$A37)*VLOOKUP($D$8,Tables!$C$1:$D$3,2,0) -> 0 | H37: =INDIRECT("'"&H$8&"'!"&$A37)*VLOOKUP($D$8,Tables!$C$1:$D$3,2,0) -> 0 | I37: =INDIRECT("'"&I$8&"'!"&$A37)*VLOOKUP($D$8,Tables!$C$1:$D$3,2,0) -> 0 | J37: =INDIRECT("'"&J$8&"'!"&$A37)*VLOOKUP($D$8,Tables!$C$1:$D$3,2,0) -> 0 | K37: =INDIRECT("'"&K$8&"'!"&$A37)*VLOOKUP($D$8,Tables!$C$1:$D$3,2,0) -> 0 | L37: =INDIRECT("'"&L$8&"'!"&$A37)*VLOOKUP($D$8,Tables!$C$1:$D$3,2,0) -> 0 | ... AM37: =INDIRECT("'"&AM$8&"'!"&$A37)*VLOOKUP($D$8,Tables!$C$1:$D$3,2,0) -> 7128.2307 | AP37: =HLOOKUP(AP$8,$E$8:$AP$230,$B37,0)/HLOOKUP(AP$8,$E$8:$AN$230,$B11,0) -> 0 | AQ37: =HLOOKUP(AQ$8,$E$8:$AP$230,$B37,0)/HLOOKUP(AQ$8,$E$8:$AN$230,$B11,0) -> 0 | AR37: =HLOOKUP(AR$8,$E$8:$AP$230,$B37,0)/HLOOKUP(AR$8,$E$8:$AN$230,$B11,0) -> 0.023718044 | AS37: =HLOOKUP(AS$8,$E$8:$AP$230,$B37,0)/HLOOKUP(AS$8,$E$8:$AN$230,$B11,0) -> 0.069218177 | AT37: =HLOOKUP(AT$8,$E$8:$AP$230,$B37,0)/HLOOKUP(AT$8,$E$8:$AN$230,$B11,0) -> 0 | AV37: =IFERROR(POWER(INDEX($E37:$AN37,AV$5)/INDEX($E37:$AN37,AV$4),1/AV$6)-1,) -> 0 | AW37: =IFERROR(POWER(INDEX($E37:$AN37,AW$5)/INDEX($E37:$AN37,AW$4),1/AW$6)-1,) -> 0 | AX37: =IFERROR(POWER(INDEX($E37:$AN37,AX$5)/INDEX($E37:$AN37,AX$4),1/AX$6)-1,) -> 0 | AY37: =IFERROR(POWER(INDEX($E37:$AN37,AY$5)/INDEX($E37:$AN37,AY$4),1/AY$6)-1,) -> 0.17258943 | AZ37: =IFERROR(POWER(INDEX($E37:$AN37,AZ$5)/INDEX($E37:$AN37,AZ$4),1/AZ$6)-1,) -> 0.081129015 | BA37: =IFERROR(POWER(INDEX($E37:$AN37,BA$5)/INDEX($E37:$AN37,BA$4),1/BA$6)-1,) -> 0.12948165
A38: =ADDRESS(MATCH($D10,'2021'!$A$1:$A$86,0),MATCH($D38,'2021'!$A$1:$AQ$1,0)) -> $AC$48 | B38: =B37+1 -> 31 | D38: Hydro | E38: =INDIRECT("'"&E$8&"'!"&$A38)*VLOOKUP($D$8,Tables!$C$1:$D$3,2,0) -> 0 | F38: =INDIRECT("'"&F$8&"'!"&$A38)*VLOOKUP($D$8,Tables!$C$1:$D$3,2,0) -> 0 | G38: =INDIRECT("'"&G$8&"'!"&$A38)*VLOOKUP($D$8,Tables!$C$1:$D$3,2,0) -> 0 | H38: =INDIRECT("'"&H$8&"'!"&$A38)*VLOOKUP($D$8,Tables!$C$1:$D$3,2,0) -> 0 | I38: =INDIRECT("'"&I$8&"'!"&$A38)*VLOOKUP($D$8,Tables!$C$1:$D$3,2,0) -> 0 | J38: =INDIRECT("'"&J$8&"'!"&$A38)*VLOOKUP($D$8,Tables!$C$1:$D$3,2,0) -> 0 | K38: =INDIRECT("'"&K$8&"'!"&$A38)*VLOOKUP($D$8,Tables!$C$1:$D$3,2,0) -> 0 | L38: =INDIRECT("'"&L$8&"'!"&$A38)*VLOOKUP($D$8,Tables!$C$1:$D$3,2,0) -> 0 | ... AM38: =INDIRECT("'"&AM$8&"'!"&$A38)*VLOOKUP($D$8,Tables!$C$1:$D$3,2,0) -> 0 | AP38: =HLOOKUP(AP$8,$E$8:$AP$230,$B38,0)/HLOOKUP(AP$8,$E$8:$AN$230,$B11,0) -> 0 | AQ38: =HLOOKUP(AQ$8,$E$8:$AP$230,$B38,0)/HLOOKUP(AQ$8,$E$8:$AN$230,$B11,0) -> 0 | AR38: =HLOOKUP(AR$8,$E$8:$AP$230,$B38,0)/HLOOKUP(AR$8,$E$8:$AN$230,$B11,0) -> 0 | AS38: =HLOOKUP(AS$8,$E$8:$AP$230,$B38,0)/HLOOKUP(AS$8,$E$8:$AN$230,$B11,0) -> 0 | AT38: =HLOOKUP(AT$8,$E$8:$AP$230,$B38,0)/HLOOKUP(AT$8,$E$8:$AN$230,$B11,0) -> 0 | AV38: =IFERROR(POWER(INDEX($E38:$AN38,AV$5)/INDEX($E38:$AN38,AV$4),1/AV$6)-1,) -> 0 | AW38: =IFERROR(POWER(INDEX($E38:$AN38,AW$5)/INDEX($E38:$AN38,AW$4),1/AW$6)-1,) -> 0 | AX38: =IFERROR(POWER(INDEX($E38:$AN38,AX$5)/INDEX($E38:$AN38,AX$4),1/AX$6)-1,) -> 0 | AY38: =IFERROR(POWER(INDEX($E38:$AN38,AY$5)/INDEX($E38:$AN38,AY$4),1/AY$6)-1,) -> 0 | AZ38: =IFERROR(POWER(INDEX($E38:$AN38,AZ$5)/INDEX($E38:$AN38,AZ$4),1/AZ$6)-1,) -> 0 | BA38: =IFERROR(POWER(INDEX($E38:$AN38,BA$5)/INDEX($E38:$AN38,BA$4),1/BA$6)-1,) -> 0
A39: =ADDRESS(MATCH($D10,'2021'!$A$1:$A$86,0),MATCH($D39,'2021'!$A$1:$AQ$1,0)) -> $AD$48 | B39: =B38+1 -> 32 | D39: Wind | E39: =INDIRECT("'"&E$8&"'!"&$A39)*VLOOKUP($D$8,Tables!$C$1:$D$3,2,0) -> 0 | F39: =INDIRECT("'"&F$8&"'!"&$A39)*VLOOKUP($D$8,Tables!$C$1:$D$3,2,0) -> 0 | G39: =INDIRECT("'"&G$8&"'!"&$A39)*VLOOKUP($D$8,Tables!$C$1:$D$3,2,0) -> 0 | H39: =INDIRECT("'"&H$8&"'!"&$A39)*VLOOKUP($D$8,Tables!$C$1:$D$3,2,0) -> 0 | I39: =INDIRECT("'"&I$8&"'!"&$A39)*VLOOKUP($D$8,Tables!$C$1:$D$3,2,0) -> 0 | J39: =INDIRECT("'"&J$8&"'!"&$A39)*VLOOKUP($D$8,Tables!$C$1:$D$3,2,0) -> 0 | K39: =INDIRECT("'"&K$8&"'!"&$A39)*VLOOKUP($D$8,Tables!$C$1:$D$3,2,0) -> 0 | L39: =INDIRECT("'"&L$8&"'!"&$A39)*VLOOKUP($D$8,Tables!$C$1:$D$3,2,0) -> 0 | ... AM39: =INDIRECT("'"&AM$8&"'!"&$A39)*VLOOKUP($D$8,Tables!$C$1:$D$3,2,0) -> 0 | AP39: =HLOOKUP(AP$8,$E$8:$AP$230,$B39,0)/HLOOKUP(AP$8,$E$8:$AN$230,$B11,0) -> 0 | AQ39: =HLOOKUP(AQ$8,$E$8:$AP$230,$B39,0)/HLOOKUP(AQ$8,$E$8:$AN$230,$B11,0) -> 0 | AR39: =HLOOKUP(AR$8,$E$8:$AP$230,$B39,0)/HLOOKUP(AR$8,$E$8:$AN$230,$B11,0) -> 0 | AS39: =HLOOKUP(AS$8,$E$8:$AP$230,$B39,0)/HLOOKUP(AS$8,$E$8:$AN$230,$B11,0) -> 0 | AT39: =HLOOKUP(AT$8,$E$8:$AP$230,$B39,0)/HLOOKUP(AT$8,$E$8:$AN$230,$B11,0) -> 0 | AV39: =IFERROR(POWER(INDEX($E39:$AN39,AV$5)/INDEX($E39:$AN39,AV$4),1/AV$6)-1,) -> 0 | AW39: =IFERROR(POWER(INDEX($E39:$AN39,AW$5)/INDEX($E39:$AN39,AW$4),1/AW$6)-1,) -> 0 | AX39: =IFERROR(POWER(INDEX($E39:$AN39,AX$5)/INDEX($E39:$AN39,AX$4),1/AX$6)-1,) -> 0 | AY39: =IFERROR(POWER(INDEX($E39:$AN39,AY$5)/INDEX($E39:$AN39,AY$4),1/AY$6)-1,) -> 0 | AZ39: =IFERROR(POWER(INDEX($E39:$AN39,AZ$5)/INDEX($E39:$AN39,AZ$4),1/AZ$6)-1,) -> 0 | BA39: =IFERROR(POWER(INDEX($E39:$AN39,BA$5)/INDEX($E39:$AN39,BA$4),1/BA$6)-1,) -> 0
A40: =ADDRESS(MATCH($D10,'2021'!$A$1:$A$86,0),MATCH($D40,'2021'!$A$1:$AQ$1,0)) -> $AE$48 | B40: =B39+1 -> 33 | D40: Biomass | E40: =INDIRECT("'"&E$8&"'!"&$A40)*VLOOKUP($D$8,Tables!$C$1:$D$3,2,0) -> 0 | F40: =INDIRECT("'"&F$8&"'!"&$A40)*VLOOKUP($D$8,Tables!$C$1:$D$3,2,0) -> 0 | G40: =INDIRECT("'"&G$8&"'!"&$A40)*VLOOKUP($D$8,Tables!$C$1:$D$3,2,0) -> 0 | H40: =INDIRECT("'"&H$8&"'!"&$A40)*VLOOKUP($D$8,Tables!$C$1:$D$3,2,0) -> 0 | I40: =INDIRECT("'"&I$8&"'!"&$A40)*VLOOKUP($D$8,Tables!$C$1:$D$3,2,0) -> 0 | J40: =INDIRECT("'"&J$8&"'!"&$A40)*VLOOKUP($D$8,Tables!$C$1:$D$3,2,0) -> 0 | K40: =INDIRECT("'"&K$8&"'!"&$A40)*VLOOKUP($D$8,Tables!$C$1:$D$3,2,0) -> 0 | L40: =INDIRECT("'"&L$8&"'!"&$A40)*VLOOKUP($D$8,Tables!$C$1:$D$3,2,0) -> 0 | ... AM40: =INDIRECT("'"&AM$8&"'!"&$A40)*VLOOKUP($D$8,Tables!$C$1:$D$3,2,0) -> 0 | AP40: =HLOOKUP(AP$8,$E$8:$AP$230,$B40,0)/HLOOKUP(AP$8,$E$8:$AN$230,$B11,0) -> 0 | AQ40: =HLOOKUP(AQ$8,$E$8:$AP$230,$B40,0)/HLOOKUP(AQ$8,$E$8:$AN$230,$B11,0) -> 0 | AR40: =HLOOKUP(AR$8,$E$8:$AP$230,$B40,0)/HLOOKUP(AR$8,$E$8:$AN$230,$B11,0) -> 0 | AS40: =HLOOKUP(AS$8,$E$8:$AP$230,$B40,0)/HLOOKUP(AS$8,$E$8:$AN$230,$B11,0) -> 0 | AT40: =HLOOKUP(AT$8,$E$8:$AP$230,$B40,0)/HLOOKUP(AT$8,$E$8:$AN$230,$B11,0) -> 0 | AV40: =IFERROR(POWER(INDEX($E40:$AN40,AV$5)/INDEX($E40:$AN40,AV$4),1/AV$6)-1,) -> 0 | AW40: =IFERROR(POWER(INDEX($E40:$AN40,AW$5)/INDEX($E40:$AN40,AW$4),1/AW$6)-1,) -> 0 | AX40: =IFERROR(POWER(INDEX($E40:$AN40,AX$5)/INDEX($E40:$AN40,AX$4),1/AX$6)-1,) -> 0 | AY40: =IFERROR(POWER(INDEX($E40:$AN40,AY$5)/INDEX($E40:$AN40,AY$4),1/AY$6)-1,) -> 0 | AZ40: =IFERROR(POWER(INDEX($E40:$AN40,AZ$5)/INDEX($E40:$AN40,AZ$4),1/AZ$6)-1,) -> 0 | BA40: =IFERROR(POWER(INDEX($E40:$AN40,BA$5)/INDEX($E40:$AN40,BA$4),1/BA$6)-1,) -> 0
A41: =ADDRESS(MATCH($D10,'2021'!$A$1:$A$86,0),MATCH($D41,'2021'!$A$1:$AQ$1,0)) -> $AF$48 | B41: =B40+1 -> 34 | D41: Renewable Waste | E41: =INDIRECT("'"&E$8&"'!"&$A41)*VLOOKUP($D$8,Tables!$C$1:$D$3,2,0) -> 0 | F41: =INDIRECT("'"&F$8&"'!"&$A41)*VLOOKUP($D$8,Tables!$C$1:$D$3,2,0) -> 0 | G41: =INDIRECT("'"&G$8&"'!"&$A41)*VLOOKUP($D$8,Tables!$C$1:$D$3,2,0) -> 0 | H41: =INDIRECT("'"&H$8&"'!"&$A41)*VLOOKUP($D$8,Tables!$C$1:$D$3,2,0) -> 0 | I41: =INDIRECT("'"&I$8&"'!"&$A41)*VLOOKUP($D$8,Tables!$C$1:$D$3,2,0) -> 0 | J41: =INDIRECT("'"&J$8&"'!"&$A41)*VLOOKUP($D$8,Tables!$C$1:$D$3,2,0) -> 0 | K41: =INDIRECT("'"&K$8&"'!"&$A41)*VLOOKUP($D$8,Tables!$C$1:$D$3,2,0) -> 0 | L41: =INDIRECT("'"&L$8&"'!"&$A41)*VLOOKUP($D$8,Tables!$C$1:$D$3,2,0) -> 0 | ... AM41: =INDIRECT("'"&AM$8&"'!"&$A41)*VLOOKUP($D$8,Tables!$C$1:$D$3,2,0) -> 0 | AP41: =HLOOKUP(AP$8,$E$8:$AP$230,$B41,0)/HLOOKUP(AP$8,$E$8:$AN$230,$B11,0) -> 0 | AQ41: =HLOOKUP(AQ$8,$E$8:$AP$230,$B41,0)/HLOOKUP(AQ$8,$E$8:$AN$230,$B11,0) -> 0 | AR41: =HLOOKUP(AR$8,$E$8:$AP$230,$B41,0)/HLOOKUP(AR$8,$E$8:$AN$230,$B11,0) -> 0 | AS41: =HLOOKUP(AS$8,$E$8:$AP$230,$B41,0)/HLOOKUP(AS$8,$E$8:$AN$230,$B11,0) -> 0 | AT41: =HLOOKUP(AT$8,$E$8:$AP$230,$B41,0)/HLOOKUP(AT$8,$E$8:$AN$230,$B11,0) -> 0 | AV41: =IFERROR(POWER(INDEX($E41:$AN41,AV$5)/INDEX($E41:$AN41,AV$4),1/AV$6)-1,) -> 0 | AW41: =IFERROR(POWER(INDEX($E41:$AN41,AW$5)/INDEX($E41:$AN41,AW$4),1/AW$6)-1,) -> 0 | AX41: =IFERROR(POWER(INDEX($E41:$AN41,AX$5)/INDEX($E41:$AN41,AX$4),1/AX$6)-1,) -> 0 | AY41: =IFERROR(POWER(INDEX($E41:$AN41,AY$5)/INDEX($E41:$AN41,AY$4),1/AY$6)-1,) -> 0 | AZ41: =IFERROR(POWER(INDEX($E41:$AN41,AZ$5)/INDEX($E41:$AN41,AZ$4),1/AZ$6)-1,) -> 0 | BA41: =IFERROR(POWER(INDEX($E41:$AN41,BA$5)/INDEX($E41:$AN41,BA$4),1/BA$6)-1,) -> 0
A42: =ADDRESS(MATCH($D10,'2021'!$A$1:$A$86,0),MATCH($D42,'2021'!$A$1:$AQ$1,0)) -> $AG$48 | B42: =B41+1 -> 35 | D42: Landfill Gas | E42: =INDIRECT("'"&E$8&"'!"&$A42)*VLOOKUP($D$8,Tables!$C$1:$D$3,2,0) -> 0 | F42: =INDIRECT("'"&F$8&"'!"&$A42)*VLOOKUP($D$8,Tables!$C$1:$D$3,2,0) -> 0 | G42: =INDIRECT("'"&G$8&"'!"&$A42)*VLOOKUP($D$8,Tables!$C$1:$D$3,2,0) -> 0 | H42: =INDIRECT("'"&H$8&"'!"&$A42)*VLOOKUP($D$8,Tables!$C$1:$D$3,2,0) -> 0 | I42: =INDIRECT("'"&I$8&"'!"&$A42)*VLOOKUP($D$8,Tables!$C$1:$D$3,2,0) -> 0 | J42: =INDIRECT("'"&J$8&"'!"&$A42)*VLOOKUP($D$8,Tables!$C$1:$D$3,2,0) -> 0 | K42: =INDIRECT("'"&K$8&"'!"&$A42)*VLOOKUP($D$8,Tables!$C$1:$D$3,2,0) -> 0 | L42: =INDIRECT("'"&L$8&"'!"&$A42)*VLOOKUP($D$8,Tables!$C$1:$D$3,2,0) -> 0 | ... AM42: =INDIRECT("'"&AM$8&"'!"&$A42)*VLOOKUP($D$8,Tables!$C$1:$D$3,2,0) -> 0 | AP42: =HLOOKUP(AP$8,$E$8:$AP$230,$B42,0)/HLOOKUP(AP$8,$E$8:$AN$230,$B11,0) -> 0 | AQ42: =HLOOKUP(AQ$8,$E$8:$AP$230,$B42,0)/HLOOKUP(AQ$8,$E$8:$AN$230,$B11,0) -> 0 | AR42: =HLOOKUP(AR$8,$E$8:$AP$230,$B42,0)/HLOOKUP(AR$8,$E$8:$AN$230,$B11,0) -> 0 | AS42: =HLOOKUP(AS$8,$E$8:$AP$230,$B42,0)/HLOOKUP(AS$8,$E$8:$AN$230,$B11,0) -> 0 | AT42: =HLOOKUP(AT$8,$E$8:$AP$230,$B42,0)/HLOOKUP(AT$8,$E$8:$AN$230,$B11,0) -> 0 | AV42: =IFERROR(POWER(INDEX($E42:$AN42,AV$5)/INDEX($E42:$AN42,AV$4),1/AV$6)-1,) -> 0 | AW42: =IFERROR(POWER(INDEX($E42:$AN42,AW$5)/INDEX($E42:$AN42,AW$4),1/AW$6)-1,) -> 0 | AX42: =IFERROR(POWER(INDEX($E42:$AN42,AX$5)/INDEX($E42:$AN42,AX$4),1/AX$6)-1,) -> 0 | AY42: =IFERROR(POWER(INDEX($E42:$AN42,AY$5)/INDEX($E42:$AN42,AY$4),1/AY$6)-1,) -> 0 | AZ42: =IFERROR(POWER(INDEX($E42:$AN42,AZ$5)/INDEX($E42:$AN42,AZ$4),1/AZ$6)-1,) -> 0 | BA42: =IFERROR(POWER(INDEX($E42:$AN42,BA$5)/INDEX($E42:$AN42,BA$4),1/BA$6)-1,) -> 0
A43: =ADDRESS(MATCH($D10,'2021'!$A$1:$A$86,0),MATCH($D43,'2021'!$A$1:$AQ$1,0)) -> $AH$48 | B43: =B42+1 -> 36 | D43: Biogas | E43: =INDIRECT("'"&E$8&"'!"&$A43)*VLOOKUP($D$8,Tables!$C$1:$D$3,2,0) -> 0 | F43: =INDIRECT("'"&F$8&"'!"&$A43)*VLOOKUP($D$8,Tables!$C$1:$D$3,2,0) -> 0 | G43: =INDIRECT("'"&G$8&"'!"&$A43)*VLOOKUP($D$8,Tables!$C$1:$D$3,2,0) -> 0 | H43: =INDIRECT("'"&H$8&"'!"&$A43)*VLOOKUP($D$8,Tables!$C$1:$D$3,2,0) -> 0 | I43: =INDIRECT("'"&I$8&"'!"&$A43)*VLOOKUP($D$8,Tables!$C$1:$D$3,2,0) -> 0 | J43: =INDIRECT("'"&J$8&"'!"&$A43)*VLOOKUP($D$8,Tables!$C$1:$D$3,2,0) -> 0 | K43: =INDIRECT("'"&K$8&"'!"&$A43)*VLOOKUP($D$8,Tables!$C$1:$D$3,2,0) -> 0 | L43: =INDIRECT("'"&L$8&"'!"&$A43)*VLOOKUP($D$8,Tables!$C$1:$D$3,2,0) -> 0 | ... AM43: =INDIRECT("'"&AM$8&"'!"&$A43)*VLOOKUP($D$8,Tables!$C$1:$D$3,2,0) -> 0 | AP43: =HLOOKUP(AP$8,$E$8:$AP$230,$B43,0)/HLOOKUP(AP$8,$E$8:$AN$230,$B11,0) -> 0 | AQ43: =HLOOKUP(AQ$8,$E$8:$AP$230,$B43,0)/HLOOKUP(AQ$8,$E$8:$AN$230,$B11,0) -> 0 | AR43: =HLOOKUP(AR$8,$E$8:$AP$230,$B43,0)/HLOOKUP(AR$8,$E$8:$AN$230,$B11,0) -> 0 | AS43: =HLOOKUP(AS$8,$E$8:$AP$230,$B43,0)/HLOOKUP(AS$8,$E$8:$AN$230,$B11,0) -> 0 | AT43: =HLOOKUP(AT$8,$E$8:$AP$230,$B43,0)/HLOOKUP(AT$8,$E$8:$AN$230,$B11,0) -> 0 | AV43: =IFERROR(POWER(INDEX($E43:$AN43,AV$5)/INDEX($E43:$AN43,AV$4),1/AV$6)-1,) -> 0 | AW43: =IFERROR(POWER(INDEX($E43:$AN43,AW$5)/INDEX($E43:$AN43,AW$4),1/AW$6)-1,) -> 0 | AX43: =IFERROR(POWER(INDEX($E43:$AN43,AX$5)/INDEX($E43:$AN43,AX$4),1/AX$6)-1,) -> 0 | AY43: =IFERROR(POWER(INDEX($E43:$AN43,AY$5)/INDEX($E43:$AN43,AY$4),1/AY$6)-1,) -> 0 | AZ43: =IFERROR(POWER(INDEX($E43:$AN43,AZ$5)/INDEX($E43:$AN43,AZ$4),1/AZ$6)-1,) -> 0 | BA43: =IFERROR(POWER(INDEX($E43:$AN43,BA$5)/INDEX($E43:$AN43,BA$4),1/BA$6)-1,) -> 0
...

Sheet Timeseries-CO2
AQ4: =AQ8-1990 -> 0 | AR4: =AR8-1990 -> 10 | AS4: =AS8-1990 -> 20 | AT4: =AT8-1990 -> 31 | AU4: =AU8-1990 -> 32 | AW4: =AW8-1990+1 -> 1 | AX4: =AX8-1990+1 -> 1 | AY4: =AY8-1990+1 -> 11 | AZ4: =AZ8-1990+1 -> 19 | BA4: =BA8-1990+1 -> 26 | BB4: =BB8-1990+1 -> 16
